Workbook

Sheet PG_Forward
A1: order_id | B1: order_line_id | C1: packing_date | D1: delivery_date | E1: sku_code | F1: seller_product_amount | G1: postpaid_amount | H1: prepaid_amount | I1: mrp | J1: total_discount_amount | K1: shipping_case | L1: total_tax_rate | M1: igst_amount | N1: cgst_amount | O1: sgst_amount | P1: tcs_amount | Q1: tds_amount | R1: commission_percentage | S1: platform_fees | T1: total_commission | U1: total_commission_plus_tcs_tds_deduction | V1: total_logistics_deduction | W1: shipping_fee | X1: fixed_fee | Y1: payment_gateway_fee | Z1: total_tax_on_logistics | AA1: article_level | AB1: shipment_zone_classification | AC1: customer_paid_amt | AD1: total_expected_settlement | AE1: total_actual_settlement | AF1: amount_pending_settlement | AG1: prepaid_commission_deduction | AH1: prepaid_logistics_deduction | AI1: prepaid_payment | AJ1: postpaid_commission_deduction | AK1: postpaid_logistics_deduction | AL1: postpaid_payment | AM1: settlement_date_prepaid_comm_deduction | AN1: settlement_date_prepaid_logistics_deduction | AO1: settlement_date_prepaid_payment | AP1: additional_amount | AQ1: taxable_amount | AR1: igst_rate | AS1: cgst_rate | AT1: sgst_rate | AU1: tcs_igst_rate | AV1: tcs_sgst_rate | AW1: tcs_cgst_rate | AX1: tds_rate | AY1: brand | AZ1: article_type | BA1: prepaid_commission_percentage | BB1: prepaid_minimum_commission | BC1: prepaid_platform_fees | BD1: prepaid_total_commission | BE1: prepaid_ship_commission_charge | BF1: prepaid_gift_commission_charge | BG1: prepaid_cod_commission_charge | BH1: prepaid_cart_discount | BI1: prepaid_coupon_discount | BJ1: postpaid_commission_percentage | BK1: postpaid_minimum_commission | BL1: postpaid_platform_fees | BM1: postpaid_total_commission | BN1: postpaid_ship_commission_charge | BO1: postpaid_gift_commission_charge | BP1: postpaid_cod_commission_charge | BQ1: postpaid_cart_discount | BR1: postpaid_coupon_discount | BS1: seller_order_id | BT1: tcs_amount_prepaid | BU1: tcs_amount_postpaid | BV1: tds_amount_prepaid | BW1: tds_amount_postpaid | BX1: Settlement_on_2025_10_03 | BY1: Settlement_on_2025_10_06 | BZ1: Settlement_on_2025_10_08 | CA1: Settlement_on_2025_10_09 | CB1: Settlement_on_2025_10_10 | CC1: Settlement_on_2025_10_13 | CD1: Settlement_on_2025_10_14 | CE1: Settlement_on_2025_10_15 | CF1: Settlement_on_2025_10_16 | CG1: Settlement_on_2025_10_17 | CH1: Settlement_on_2025_10_23 | CI1: Settlement_on_2025_10_24 | CJ1: Settlement_on_2025_10_27 | CK1: Settlement_on_2025_10_28 | CL1: Settlement_on_2025_10_29 | CM1: Settlement_on_2025_10_30 | CN1: SettlementOn16_ | CO1: SettlementOn17_ | CP1: SettlementOn18_ | CQ1: SettlementOn19_ | CR1: SettlementOn20_ | CS1: SettlementOn21_ | CT1: SettlementOn22_ | CU1: SettlementOn23_ | CV1: SettlementOn24_ | CW1: SettlementOn25_ | CX1: SettlementOn26_ | CY1: SettlementOn27_ | CZ1: SettlementOn28_ | DA1: SettlementOn29_ | DB1: SettlementOn30_ | DC1: Customer_Paid | DD1: Commission | DE1: Tax_On_Commission | DF1: Logistics | DG1: GST_taxes | DH1: Myntra_Settlement
A2: 8743896489 | B2: 10743901048 | C2: 45939.449 | D2: 45942.572 | E2: TIKICLST113026317 | F2: 2410 | G2: 2410 | H2: 0 | I2: 3500 | J2: 884 | K2: Inter-State | L2: 5 | M2: 114.76 | N2: 0 | O2: 0 | P2: 11.476 | Q2: 2.295 | R2: 24.78 | S2: 597.198 | T2: -597.198 | U2: -610.969 | V2: -71.98 | W2: 0 | X2: 61 | Y2: 0 | Z2: 10.98 | AA2: 1 | AB2: ZONAL | AC2: 2616 | AD2: 1727.051 | AE2: 1727.051 | AF2: 0 | AG2: 0 | AI2: 0 | AJ2: -610.969 | AK2: -71.98 | AL2: 2410 | AP2: 0 | AQ2: 2295.24 | AR2: 5 | AS2: 0 | AT2: 0 | AU2: 0.5 | AV2: 0 | AW2: 0 | AX2: 0.1 | AY2: Tiny Kingdom | AZ2: Clothing Set | BC2: 0 | BD2: 0 | BE2: 0 | BF2: 0 | BG2: 0 | BJ2: 24.78 | BK2: 0 | BL2: 597.198 | BM2: -597.198 | BN2: 0 | BO2: 0 | BP2: 0 | BQ2: 884 | BR2: 2.29524 | BS2: aa6d8459-4827-4236-b8a7-a81eef5aaf11 | BT2: 0 | BU2: 11.476 | BV2: 0 | BW2: 2.295 | BX2: 0 | BY2: 0 | BZ2: 0 | CA2: 0 | CB2: 0 | CC2: 0 | CD2: 0 | CE2: 0 | CF2: 0 | CG2: 0 | CH2: 0 | CI2: 0 | CJ2: 1727.051 | CK2: 0 | CL2: 0 | CM2: 0 | CN2: 0 | CO2: 0 | CP2: 0 | CQ2: 0 | CR2: 0 | CS2: 0 | CT2: 0 | CU2: 0 | CV2: 0 | CW2: 0 | CX2: 0 | CY2: 0 | CZ2: 0 | DA2: 0 | DB2: 0 | DC2: =IFERROR(G2,0)+IFERROR(H2,0) -> 2410 | DD2: =ABS(IFERROR(T2,0)) -> 597.198 | DE2: =ABS(IFERROR(P2,0)+IFERROR(Q2,0)) -> 13.771 | DF2: =ABS(IFERROR(AH2,0))+ABS(IFERROR(AK2,0))+IFERROR(W2,0) -> 71.98 | DG2: =IFERROR(M2,0)+IFERROR(N2,0)+IFERROR(O2,0)+IFERROR(P2,0) -> 126.236 | DH2: 1727.051
A3: 8746383853 | B3: 10746400495 | C3: 45940.808 | D3: 45946.475 | E3: TIKILHNC118421496 | F3: 2385 | G3: 0 | H3: 2385 | I3: 3000 | J3: 385 | K3: Inter-State | L3: 5 | M3: 113.57 | N3: 0 | O3: 0 | P3: 11.357 | Q3: 2.271 | R3: 17.7 | S3: 422.145 | T3: -422.145 | U3: -435.773 | V3: -71.98 | W3: 0 | X3: 61 | Y3: 0 | Z3: 10.98 | AA3: 2 | AB3: NATIONAL | AC3: 2615 | AD3: 1877.247 | AE3: 1877.247 | AF3: 0 | AG3: -435.773 | AH3: -71.98 | AI3: 2385 | AJ3: 0 | AL3: 0 | AM3: 45960 | AN3: 45960 | AO3: 45960 | AP3: 0 | AQ3: 2271.43 | AR3: 5 | AS3: 0 | AT3: 0 | AU3: 0.5 | AV3: 0 | AW3: 0 | AX3: 0.1 | AY3: Tiny Kingdom | AZ3: Sarees | BA3: 17.7 | BB3: 0 | BC3: 422.145 | BD3: -422.145 | BE3: 0 | BF3: 0 | BG3: 0 | BH3: 385 | BI3: 2.27143 | BL3: 0 | BM3: 0 | BN3: 0 | BO3: 0 | BP3: 0 | BS3: 498b0126-4b67-44e1-9f5c-40372d11a4b3 | BT3: 11.357 | BU3: 0 | BV3: 2.271 | BW3: 0 | BX3: 0 | BY3: 0 | BZ3: 0 | CA3: 0 | CB3: 0 | CC3: 0 | CD3: 0 | CE3: 0 | CF3: 0 | CG3: 0 | CH3: 0 | CI3: 0 | CJ3: 0 | CK3: 0 | CL3: 0 | CM3: 1877.247 | CN3: 0 | CO3: 0 | CP3: 0 | CQ3: 0 | CR3: 0 | CS3: 0 | CT3: 0 | CU3: 0 | CV3: 0 | CW3: 0 | CX3: 0 | CY3: 0 | CZ3: 0 | DA3: 0 | DB3: 0 | DC3: =IFERROR(G3,0)+IFERROR(H3,0) -> 2385 | DD3: =ABS(IFERROR(T3,0)) -> 422.145 | DE3: =ABS(IFERROR(P3,0)+IFERROR(Q3,0)) -> 13.628 | DF3: =ABS(IFERROR(AH3,0))+ABS(IFERROR(AK3,0))+IFERROR(W3,0) -> 71.98 | DG3: =IFERROR(M3,0)+IFERROR(N3,0)+IFERROR(O3,0)+IFERROR(P3,0) -> 124.927 | DH3: 1877.247
A4: 8725799225 | B4: 10725751253 | C4: 45931.8 | D4: 45936.447 | E4: TNBYCLST101412227 | F4: 2556 | G4: 0 | H4: 2556 | I4: 3250 | J4: 488 | K4: Intra-State | L4: 5 | M4: 0 | N4: 60.86 | O4: 60.86 | P4: 12.171 | Q4: 2.434 | R4: 25.96 | S4: 663.538 | T4: -663.538 | U4: -678.143 | V4: -71.98 | W4: 0 | X4: 61 | Y4: 0 | Z4: 10.98 | AA4: 1 | AB4: ZONAL | AC4: 2762 | AD4: 1805.877 | AE4: 1805.877 | AF4: 0 | AG4: -678.143 | AH4: -71.98 | AI4: 2556 | AJ4: 0 | AL4: 0 | AM4: 45953 | AN4: 45953 | AO4: 45953 | AP4: 0 | AQ4: 2434.28 | AR4: 0 | AS4: 2.5 | AT4: 2.5 | AU4: 0 | AV4: 0.25 | AW4: 0.25 | AX4: 0.1 | AY4: Tiny Baby | AZ4: Clothing Set | BA4: 25.96 | BB4: 0 | BC4: 663.538 | BD4: -663.538 | BE4: 0 | BF4: 0 | BG4: 0 | BH4: 488 | BI4: 2.43428 | BL4: 0 | BM4: 0 | BN4: 0 | BO4: 0 | BP4: 0 | BS4: a7ad35a9-eb5c-41c7-8007-586d66487e24 | BT4: 12.171 | BU4: 0 | BV4: 2.434 | BW4: 0 | BX4: 0 | BY4: 0 | BZ4: 0 | CA4: 0 | CB4: 0 | CC4: 0 | CD4: 0 | CE4: 0 | CF4: 0 | CG4: 0 | CH4: 1805.877 | CI4: 0 | CJ4: 0 | CK4: 0 | CL4: 0 | CM4: 0 | CN4: 0 | CO4: 0 | CP4: 0 | CQ4: 0 | CR4: 0 | CS4: 0 | CT4: 0 | CU4: 0 | CV4: 0 | CW4: 0 | CX4: 0 | CY4: 0 | CZ4: 0 | DA4: 0 | DB4: 0 | DC4: =IFERROR(G4,0)+IFERROR(H4,0) -> 2556 | DD4: =ABS(IFERROR(T4,0)) -> 663.538 | DE4: =ABS(IFERROR(P4,0)+IFERROR(Q4,0)) -> 14.605 | DF4: =ABS(IFERROR(AH4,0))+ABS(IFERROR(AK4,0))+IFERROR(W4,0) -> 71.98 | DG4: =IFERROR(M4,0)+IFERROR(N4,0)+IFERROR(O4,0)+IFERROR(P4,0) -> 133.891 | DH4: 1805.877
A5: 8718239977 | B5: 10718182238 | C5: 45930.615 | D5: 45934.859 | E5: TIKILHNC115963260 | F5: 3789 | G5: 0 | H5: 3788.99 | I5: 4250 | J5: 255 | K5: Inter-State | L5: 18 | M5: 577.98 | N5: 0 | O5: 0 | P5: 16.055 | Q5: 3.211 | R5: 24.78 | S5: 938.912 | T5: -938.912 | U5: -958.178 | V5: -71.98 | W5: 0 | X5: 61 | Y5: 0 | Z5: 10.98 | AA5: 1 | AB5: ZONAL | AC5: 3995 | AD5: 2758.832 | AE5: 2758.832 | AF5: 0 | AG5: -958.178 | AH5: -71.98 | AI5: 3788.99 | AJ5: 0 | AL5: 0 | AM5: 45953 | AN5: 45953 | AO5: 45953 | AP5: 0 | AQ5: 3211.02 | AR5: 18 | AS5: 0 | AT5: 0 | AU5: 0.5 | AV5: 0 | AW5: 0 | AX5: 0.1 | AY5: Tiny Kingdom | AZ5: Lehenga Choli | BA5: 24.78 | BB5: 0 | BC5: 938.912 | BD5: -938.912 | BE5: 0 | BF5: 0 | BG5: 0 | BH5: 255 | BI5: 3.21102 | BL5: 0 | BM5: 0 | BN5: 0 | BO5: 0 | BP5: 0 | BS5: 3136d9a9-9225-499d-8a5e-3fb44a352e77 | BT5: 16.055 | BU5: 0 | BV5: 3.211 | BW5: 0 | BX5: 0 | BY5: 0 | BZ5: 0 | CA5: 0 | CB5: 0 | CC5: 0 | CD5: 0 | CE5: 0 | CF5: 0 | CG5: 0 | CH5: 2758.832 | CI5: 0 | CJ5: 0 | CK5: 0 | CL5: 0 | CM5: 0 | CN5: 0 | CO5: 0 | CP5: 0 | CQ5: 0 | CR5: 0 | CS5: 0 | CT5: 0 | CU5: 0 | CV5: 0 | CW5: 0 | CX5: 0 | CY5: 0 | CZ5: 0 | DA5: 0 | DB5: 0 | DC5: =IFERROR(G5,0)+IFERROR(H5,0) -> 3788.99 | DD5: =ABS(IFERROR(T5,0)) -> 938.912 | DE5: =ABS(IFERROR(P5,0)+IFERROR(Q5,0)) -> 19.266 | DF5: =ABS(IFERROR(AH5,0))+ABS(IFERROR(AK5,0))+IFERROR(W5,0) -> 71.98 | DG5: =IFERROR(M5,0)+IFERROR(N5,0)+IFERROR(O5,0)+IFERROR(P5,0) -> 594.035 | DH5: 2758.832
A6: 8752499712 | B6: 10752538871 | C6: 45943.449 | D6: 45946.55 | E6: BETYDRSS77160920 | F6: 2150 | G6: 0 | H6: 2150 | I6: 5500 | J6: 3144 | K6: Inter-State | L6: 5 | M6: 102.38 | N6: 0 | O6: 0 | P6: 10.238 | Q6: 2.048 | R6: 31.86 | S6: 684.99 | T6: -684.99 | U6: -697.276 | V6: -71.98 | W6: 0 | X6: 61 | Y6: 0 | Z6: 10.98 | AA6: 1 | AB6: ZONAL | AC6: 2356 | AD6: 1380.744 | AE6: 1380.744 | AF6: 0 | AG6: -697.276 | AH6: -71.98 | AI6: 2150 | AJ6: 0 | AL6: 0 | AM6: 45960 | AN6: 45960 | AO6: 45960 | AP6: 0 | AQ6: 2047.62 | AR6: 5 | AS6: 0 | AT6: 0 | AU6: 0.5 | AV6: 0 | AW6: 0 | AX6: 0.1 | AY6: BETTY | AZ6: Dresses | BA6: 31.86 | BB6: 0 | BC6: 684.99 | BD6: -684.99 | BE6: 0 | BF6: 0 | BG6: 0 | BH6: 3144 | BI6: 2.04762 | BL6: 0 | BM6: 0 | BN6: 0 | BO6: 0 | BP6: 0 | BS6: 345d8774-a51e-42c7-b137-0272cd9ee960 | BT6: 10.238 | BU6: 0 | BV6: 2.048 | BW6: 0 | BX6: 0 | BY6: 0 | BZ6: 0 | CA6: 0 | CB6: 0 | CC6: 0 | CD6: 0 | CE6: 0 | CF6: 0 | CG6: 0 | CH6: 0 | CI6: 0 | CJ6: 0 | CK6: 0 | CL6: 0 | CM6: 1380.744 | CN6: 0 | CO6: 0 | CP6: 0 | CQ6: 0 | CR6: 0 | CS6: 0 | CT6: 0 | CU6: 0 | CV6: 0 | CW6: 0 | CX6: 0 | CY6: 0 | CZ6: 0 | DA6: 0 | DB6: 0 | DC6: =IFERROR(G6,0)+IFERROR(H6,0) -> 2150 | DD6: =ABS(IFERROR(T6,0)) -> 684.99 | DE6: =ABS(IFERROR(P6,0)+IFERROR(Q6,0)) -> 12.286 | DF6: =ABS(IFERROR(AH6,0))+ABS(IFERROR(AK6,0))+IFERROR(W6,0) -> 71.98 | DG6: =IFERROR(M6,0)+IFERROR(N6,0)+IFERROR(O6,0)+IFERROR(P6,0) -> 112.618 | DH6: 1380.744
A7: 8727502935 | B7: 10727456914 | C7: 45933.481 | D7: 45935.695 | E7: TIKIDRSS113553908 | F7: 3119 | G7: 3119 | H7: 0 | I7: 3500 | J7: 175 | K7: Intra-State | L7: 18 | M7: 0 | N7: 237.89 | O7: 237.89 | P7: 13.216 | Q7: 2.643 | R7: 21.24 | S7: 662.476 | T7: -662.476 | U7: -678.335 | V7: -71.98 | W7: 0 | X7: 61 | Y7: 0 | Z7: 10.98 | AA7: 1 | AB7: LOCAL | AC7: 3325 | AD7: 2368.685 | AE7: 2368.685 | AF7: 0 | AG7: 0 | AI7: 0 | AJ7: -678.335 | AK7: -71.98 | AL7: 3119 | AP7: 0 | AQ7: 2643.22 | AR7: 0 | AS7: 9 | AT7: 9 | AU7: 0 | AV7: 0.25 | AW7: 0.25 | AX7: 0.1 | AY7: Tiny Kingdom | AZ7: Dresses | BC7: 0 | BD7: 0 | BE7: 0 | BF7: 0 | BG7: 0 | BJ7: 21.24 | BK7: 0 | BL7: 662.476 | BM7: -662.476 | BN7: 0 | BO7: 0 | BP7: 0 | BQ7: 175 | BR7: 2.64322 | BS7: 4fb2c573-ee87-49ef-a5e5-dc738d4bf435 | BT7: 0 | BU7: 13.216 | BV7: 0 | BW7: 2.643 | BX7: 0 | BY7: 0 | BZ7: 0 | CA7: 0 | CB7: 0 | CC7: 0 | CD7: 0 | CE7: 0 | CF7: 0 | CG7: 0 | CH7: 2368.685 | CI7: 0 | CJ7: 0 | CK7: 0 | CL7: 0 | CM7: 0 | CN7: 0 | CO7: 0 | CP7: 0 | CQ7: 0 | CR7: 0 | CS7: 0 | CT7: 0 | CU7: 0 | CV7: 0 | CW7: 0 | CX7: 0 | CY7: 0 | CZ7: 0 | DA7: 0 | DB7: 0 | DC7: =IFERROR(G7,0)+IFERROR(H7,0) -> 3119 | DD7: =ABS(IFERROR(T7,0)) -> 662.476 | DE7: =ABS(IFERROR(P7,0)+IFERROR(Q7,0)) -> 15.859 | DF7: =ABS(IFERROR(AH7,0))+ABS(IFERROR(AK7,0))+IFERROR(W7,0) -> 71.98 | DG7: =IFERROR(M7,0)+IFERROR(N7,0)+IFERROR(O7,0)+IFERROR(P7,0) -> 488.996 | DH7: 2368.685
A8: 8663926203 | B8: 10663850265 | C8: 45912.803 | D8: 45916.753 | E8: TIKIDRSS97455131 | F8: 1454 | G8: 1454 | H8: 0 | I8: 3250 | J8: 1625 | K8: Inter-State | L8: 12 | M8: 155.79 | N8: 0 | O8: 0 | P8: 6.491 | Q8: 1.298 | R8: 22.42 | S8: 325.987 | T8: -325.987 | U8: -333.776 | V8: -53.1 | W8: 0 | X8: 45 | Y8: 0 | Z8: 8.1 | AA8: 1 | AB8: NATIONAL | AC8: 1625 | AD8: 1067.124 | AE8: 1067.124 | AF8: 0 | AG8: 0 | AI8: 0 | AJ8: -333.776 | AK8: -53.1 | AL8: 1454 | AP8: 0 | AQ8: 1298.21 | AR8: 12 | AS8: 0 | AT8: 0 | AU8: 0.5 | AV8: 0 | AW8: 0 | AX8: 0.1 | AY8: Tiny Kingdom | AZ8: Dresses | BC8: 0 | BD8: 0 | BE8: 0 | BF8: 0 | BG8: 0 | BJ8: 22.42 | BK8: 0 | BL8: 325.987 | BM8: -325.987 | BN8: 0 | BO8: 0 | BP8: 0 | BQ8: 1625 | BR8: 1.29821 | BS8: 020eb887-9733-4981-833d-54a0cda5413d | BT8: 0 | BU8: 6.491 | BV8: 0 | BW8: 1.298 | BX8: 1067.124 | BY8: 0 | BZ8: 0 | CA8: 0 | CB8: 0 | CC8: 0 | CD8: 0 | CE8: 0 | CF8: 0 | CG8: 0 | CH8: 0 | CI8: 0 | CJ8: 0 | CK8: 0 | CL8: 0 | CM8: 0 | CN8: 0 | CO8: 0 | CP8: 0 | CQ8: 0 | CR8: 0 | CS8: 0 | CT8: 0 | CU8: 0 | CV8: 0 | CW8: 0 | CX8: 0 | CY8: 0 | CZ8: 0 | DA8: 0 | DB8: 0 | DC8: =IFERROR(G8,0)+IFERROR(H8,0) -> 1454 | DD8: =ABS(IFERROR(T8,0)) -> 325.987 | DE8: =ABS(IFERROR(P8,0)+IFERROR(Q8,0)) -> 7.789 | DF8: =ABS(IFERROR(AH8,0))+ABS(IFERROR(AK8,0))+IFERROR(W8,0) -> 53.1 | DG8: =IFERROR(M8,0)+IFERROR(N8,0)+IFERROR(O8,0)+IFERROR(P8,0) -> 162.281 | DH8: 1067.124
A9: 8689247485 | B9: 10689175468 | C9: 45922.443 | D9: 45926.408 | E9: TIKICLST112314232 | F9: 3564 | G9: 0 | H9: 3564 | I9: 4000 | J9: 230 | K9: Inter-State | L9: 18 | M9: 543.66 | N9: 0 | O9: 0 | P9: 15.102 | Q9: 3.02 | R9: 24.78 | S9: 883.159 | T9: -883.159 | U9: -901.281 | V9: -71.98 | W9: 0 | X9: 61 | Y9: 0 | Z9: 10.98 | AA9: 1 | AB9: NATIONAL | AC9: 3770 | AD9: 2590.739 | AE9: 2590.739 | AF9: 0 | AG9: -901.281 | AH9: -71.98 | AI9: 3564 | AJ9: 0 | AL9: 0 | AM9: 45940 | AN9: 45940 | AO9: 45940 | AP9: 0 | AQ9: 3020.34 | AR9: 18 | AS9: 0 | AT9: 0 | AU9: 0.5 | AV9: 0 | AW9: 0 | AX9: 0.1 | AY9: Tiny Kingdom | AZ9: Clothing Set | BA9: 24.78 | BB9: 0 | BC9: 883.159 | BD9: -883.159 | BE9: 0 | BF9: 0 | BG9: 0 | BH9: 230 | BI9: 3.02034 | BL9: 0 | BM9: 0 | BN9: 0 | BO9: 0 | BP9: 0 | BS9: ef20eac0-eb9e-4fa8-9c55-50cc8c975f8d | BT9: 15.102 | BU9: 0 | BV9: 3.02 | BW9: 0 | BX9: 0 | BY9: 0 | BZ9: 0 | CA9: 0 | CB9: 2590.739 | CC9: 0 | CD9: 0 | CE9: 0 | CF9: 0 | CG9: 0 | CH9: 0 | CI9: 0 | CJ9: 0 | CK9: 0 | CL9: 0 | CM9: 0 | CN9: 0 | CO9: 0 | CP9: 0 | CQ9: 0 | CR9: 0 | CS9: 0 | CT9: 0 | CU9: 0 | CV9: 0 | CW9: 0 | CX9: 0 | CY9: 0 | CZ9: 0 | DA9: 0 | DB9: 0 | DC9: =IFERROR(G9,0)+IFERROR(H9,0) -> 3564 | DD9: =ABS(IFERROR(T9,0)) -> 883.159 | DE9: =ABS(IFERROR(P9,0)+IFERROR(Q9,0)) -> 18.122 | DF9: =ABS(IFERROR(AH9,0))+ABS(IFERROR(AK9,0))+IFERROR(W9,0) -> 71.98 | DG9: =IFERROR(M9,0)+IFERROR(N9,0)+IFERROR(O9,0)+IFERROR(P9,0) -> 558.762 | DH9: 2590.739
A10: 8694687361 | B10: 10694615798 | C10: 45922.443 | D10: 45925.467 | E10: TIKIDRSS101406984 | F10: 3143 | G10: 0 | H10: 3142.99 | I10: 4000 | J10: 651 | K10: Intra-State | L10: 18 | M10: 0 | N10: 239.72 | O10: 239.72 | P10: 13.318 | Q10: 2.664 | R10: 21.24 | S10: 667.571 | T10: -667.571 | U10: -683.553 | V10: -71.98 | W10: 0 | X10: 61 | Y10: 0 | Z10: 10.98 | AA10: 1 | AB10: ZONAL | AC10: 3349 | AD10: 2387.457 | AE10: 2387.457 | AF10: 0 | AG10: -683.553 | AH10: -71.98 | AI10: 3142.99 | AJ10: 0 | AL10: 0 | AM10: 45939 | AN10: 45939 | AO10: 45939 | AP10: 0 | AQ10: 2663.56 | AR10: 0 | AS10: 9 | AT10: 9 | AU10: 0 | AV10: 0.25 | AW10: 0.25 | AX10: 0.1 | AY10: Tiny Kingdom | AZ10: Dresses | BA10: 21.24 | BB10: 0 | BC10: 667.571 | BD10: -667.571 | BE10: 0 | BF10: 0 | BG10: 0 | BH10: 651 | BI10: 2.66356 | BL10: 0 | BM10: 0 | BN10: 0 | BO10: 0 | BP10: 0 | BS10: 8104d6da-dfc6-471e-9550-5e477814e850 | BT10: 13.318 | BU10: 0 | BV10: 2.664 | BW10: 0 | BX10: 0 | BY10: 0 | BZ10: 0 | CA10: 2387.457 | CB10: 0 | CC10: 0 | CD10: 0 | CE10: 0 | CF10: 0 | CG10: 0 | CH10: 0 | CI10: 0 | CJ10: 0 | CK10: 0 | CL10: 0 | CM10: 0 | CN10: 0 | CO10: 0 | CP10: 0 | CQ10: 0 | CR10: 0 | CS10: 0 | CT10: 0 | CU10: 0 | CV10: 0 | CW10: 0 | CX10: 0 | CY10: 0 | CZ10: 0 | DA10: 0 | DB10: 0 | DC10: =IFERROR(G10,0)+IFERROR(H10,0) -> 3142.99 | DD10: =ABS(IFERROR(T10,0)) -> 667.571 | DE10: =ABS(IFERROR(P10,0)+IFERROR(Q10,0)) -> 15.982 | DF10: =ABS(IFERROR(AH10,0))+ABS(IFERROR(AK10,0))+IFERROR(W10,0) -> 71.98 | DG10: =IFERROR(M10,0)+IFERROR(N10,0)+IFERROR(O10,0)+IFERROR(P10,0) -> 492.758 | DH10: 2387.457
A11: 8687587807 | B11: 10687515231 | C11: 45922.443 | D11: 45927.651 | E11: TIKICLST113026327 | F11: 3104 | G11: 0 | H11: 3104 | I11: 3500 | J11: 190 | K11: Inter-State | L11: 18 | M11: 473.49 | N11: 0 | O11: 0 | P11: 13.153 | Q11: 2.631 | R11: 24.78 | S11: 769.171 | T11: -769.171 | U11: -784.955 | V11: -71.98 | W11: 0 | X11: 61 | Y11: 0 | Z11: 10.98 | AA11: 1 | AB11: NATIONAL | AC11: 3310 | AD11: 2247.065 | AE11: 2247.065 | AF11: 0 | AG11: -784.955 | AH11: -71.98 | AI11: 3104 | AJ11: 0 | AL11: 0 | AM11: 45943 | AN11: 45943 | AO11: 45943 | AP11: 0 | AQ11: 2630.51 | AR11: 18 | AS11: 0 | AT11: 0 | AU11: 0.5 | AV11: 0 | AW11: 0 | AX11: 0.1 | AY11: Tiny Kingdom | AZ11: Clothing Set | BA11: 24.78 | BB11: 0 | BC11: 769.171 | BD11: -769.171 | BE11: 0 | BF11: 0 | BG11: 0 | BH11: 190 | BI11: 2.63051 | BL11: 0 | BM11: 0 | BN11: 0 | BO11: 0 | BP11: 0 | BS11: 768f2142-4660-434c-94b3-30311bd81658 | BT11: 13.153 | BU11: 0 | BV11: 2.631 | BW11: 0 | BX11: 0 | BY11: 0 | BZ11: 0 | CA11: 0 | CB11: 0 | CC11: 2247.065 | CD11: 0 | CE11: 0 | CF11: 0 | CG11: 0 | CH11: 0 | CI11: 0 | CJ11: 0 | CK11: 0 | CL11: 0 | CM11: 0 | CN11: 0 | CO11: 0 | CP11: 0 | CQ11: 0 | CR11: 0 | CS11: 0 | CT11: 0 | CU11: 0 | CV11: 0 | CW11: 0 | CX11: 0 | CY11: 0 | CZ11: 0 | DA11: 0 | DB11: 0 | DC11: =IFERROR(G11,0)+IFERROR(H11,0) -> 3104 | DD11: =ABS(IFERROR(T11,0)) -> 769.171 | DE11: =ABS(IFERROR(P11,0)+IFERROR(Q11,0)) -> 15.784 | DF11: =ABS(IFERROR(AH11,0))+ABS(IFERROR(AK11,0))+IFERROR(W11,0) -> 71.98 | DG11: =IFERROR(M11,0)+IFERROR(N11,0)+IFERROR(O11,0)+IFERROR(P11,0) -> 486.643 | DH11: 2247.065
A12: 8688316765 | B12: 10688244480 | C12: 45922.443 | D12: 45927.529 | E12: TIKIDRSS103325542 | F12: 2594 | G12: 0 | H12: 2594 | I12: 3500 | J12: 700 | K12: Inter-State | L12: 5 | M12: 123.52 | N12: 0 | O12: 0 | P12: 12.352 | Q12: 2.47 | R12: 21.24 | S12: 550.966 | T12: -550.966 | U12: -565.788 | V12: -71.98 | W12: 0 | X12: 61 | Y12: 0 | Z12: 10.98 | AA12: 1 | AB12: NATIONAL | AC12: 2800 | AD12: 1956.232 | AE12: 1956.232 | AF12: 0 | AG12: -565.788 | AH12: -71.98 | AI12: 2594 | AJ12: 0 | AL12: 0 | AM12: 45943 | AN12: 45943 | AO12: 45943 | AP12: 0 | AQ12: 2470.48 | AR12: 5 | AS12: 0 | AT12: 0 | AU12: 0.5 | AV12: 0 | AW12: 0 | AX12: 0.1 | AY12: Tiny Kingdom | AZ12: Dresses | BA12: 21.24 | BB12: 0 | BC12: 550.966 | BD12: -550.966 | BE12: 0 | BF12: 0 | BG12: 0 | BH12: 700 | BI12: 2.47048 | BL12: 0 | BM12: 0 | BN12: 0 | BO12: 0 | BP12: 0 | BS12: 15c4a032-8fd2-4971-aa2f-d5d0a02f3f28 | BT12: 12.352 | BU12: 0 | BV12: 2.47 | BW12: 0 | BX12: 0 | BY12: 0 | BZ12: 0 | CA12: 0 | CB12: 0 | CC12: 1956.232 | CD12: 0 | CE12: 0 | CF12: 0 | CG12: 0 | CH12: 0 | CI12: 0 | CJ12: 0 | CK12: 0 | CL12: 0 | CM12: 0 | CN12: 0 | CO12: 0 | CP12: 0 | CQ12: 0 | CR12: 0 | CS12: 0 | CT12: 0 | CU12: 0 | CV12: 0 | CW12: 0 | CX12: 0 | CY12: 0 | CZ12: 0 | DA12: 0 | DB12: 0 | DC12: =IFERROR(G12,0)+IFERROR(H12,0) -> 2594 | DD12: =ABS(IFERROR(T12,0)) -> 550.966 | DE12: =ABS(IFERROR(P12,0)+IFERROR(Q12,0)) -> 14.822 | DF12: =ABS(IFERROR(AH12,0))+ABS(IFERROR(AK12,0))+IFERROR(W12,0) -> 71.98 | DG12: =IFERROR(M12,0)+IFERROR(N12,0)+IFERROR(O12,0)+IFERROR(P12,0) -> 135.872 | DH12: 1956.232
A13: 8717002058 | B13: 10716943116 | C13: 45930.615 | D13: 45934.626 | E13: TIKIDRSS106641723 | F13: 3119 | G13: 0 | H13: 3118.99 | I13: 3750 | J13: 425 | K13: Inter-State | L13: 18 | M13: 475.78 | N13: 0 | O13: 0 | P13: 13.216 | Q13: 2.643 | R13: 21.24 | S13: 662.473 | T13: -662.473 | U13: -678.332 | V13: -71.98 | W13: 0 | X13: 61 | Y13: 0 | Z13: 10.98 | AA13: 1 | AB13: ZONAL | AC13: 3325 | AD13: 2368.678 | AE13: 2368.678 | AF13: 0 | AG13: -678.332 | AH13: -71.98 | AI13: 3118.99 | AJ13: 0 | AL13: 0 | AM13: 45953 | AN13: 45953 | AO13: 45953 | AP13: 0 | AQ13: 2643.22 | AR13: 18 | AS13: 0 | AT13: 0 | AU13: 0.5 | AV13: 0 | AW13: 0 | AX13: 0.1 | AY13: Tiny Kingdom | AZ13: Dresses | BA13: 21.24 | BB13: 0 | BC13: 662.473 | BD13: -662.473 | BE13: 0 | BF13: 0 | BG13: 0 | BH13: 425 | BI13: 2.64322 | BL13: 0 | BM13: 0 | BN13: 0 | BO13: 0 | BP13: 0 | BS13: 4c3bf5af-4258-40fa-bbbf-029941cc4ade | BT13: 13.216 | BU13: 0 | BV13: 2.643 | BW13: 0 | BX13: 0 | BY13: 0 | BZ13: 0 | CA13: 0 | CB13: 0 | CC13: 0 | CD13: 0 | CE13: 0 | CF13: 0 | CG13: 0 | CH13: 2368.678 | CI13: 0 | CJ13: 0 | CK13: 0 | CL13: 0 | CM13: 0 | CN13: 0 | CO13: 0 | CP13: 0 | CQ13: 0 | CR13: 0 | CS13: 0 | CT13: 0 | CU13: 0 | CV13: 0 | CW13: 0 | CX13: 0 | CY13: 0 | CZ13: 0 | DA13: 0 | DB13: 0 | DC13: =IFERROR(G13,0)+IFERROR(H13,0) -> 3118.99 | DD13: =ABS(IFERROR(T13,0)) -> 662.473 | DE13: =ABS(IFERROR(P13,0)+IFERROR(Q13,0)) -> 15.859 | DF13: =ABS(IFERROR(AH13,0))+ABS(IFERROR(AK13,0))+IFERROR(W13,0) -> 71.98 | DG13: =IFERROR(M13,0)+IFERROR(N13,0)+IFERROR(O13,0)+IFERROR(P13,0) -> 488.996 | DH13: 2368.678
A14: 8670163180 | B14: 10670087339 | C14: 45915.472 | D14: 45918.742 | E14: TIKIDRSS101150929 | F14: 1610 | G14: 0 | H14: 1610 | I14: 3750 | J14: 1875 | K14: Inter-State | L14: 12 | M14: 172.5 | N14: 0 | O14: 0 | P14: 7.188 | Q14: 1.438 | R14: 22.42 | S14: 360.962 | T14: -360.962 | U14: -369.588 | V14: -53.1 | W14: 0 | X14: 45 | Y14: 0 | Z14: 8.1 | AA14: 1 | AB14: NATIONAL | AC14: 1781 | AD14: 1187.312 | AE14: 1187.312 | AF14: 0 | AG14: -369.588 | AH14: -53.1 | AI14: 1610 | AJ14: 0 | AL14: 0 | AM14: 45933 | AN14: 45933 | AO14: 45933 | AP14: 0 | AQ14: 1437.5 | AR14: 12 | AS14: 0 | AT14: 0 | AU14: 0.5 | AV14: 0 | AW14: 0 | AX14: 0.1 | AY14: Tiny Kingdom | AZ14: Dresses | BA14: 22.42 | BB14: 0 | BC14: 360.962 | BD14: -360.962 | BE14: 0 | BF14: 0 | BG14: 0 | BH14: 1875 | BI14: 1.4375 | BL14: 0 | BM14: 0 | BN14: 0 | BO14: 0 | BP14: 0 | BS14: 80f9d3f0-c04f-4328-aa94-90b539e7b635 | BT14: 7.188 | BU14: 0 | BV14: 1.438 | BW14: 0 | BX14: 1187.312 | BY14: 0 | BZ14: 0 | CA14: 0 | CB14: 0 | CC14: 0 | CD14: 0 | CE14: 0 | CF14: 0 | CG14: 0 | CH14: 0 | CI14: 0 | CJ14: 0 | CK14: 0 | CL14: 0 | CM14: 0 | CN14: 0 | CO14: 0 | CP14: 0 | CQ14: 0 | CR14: 0 | CS14: 0 | CT14: 0 | CU14: 0 | CV14: 0 | CW14: 0 | CX14: 0 | CY14: 0 | CZ14: 0 | DA14: 0 | DB14: 0 | DC14: =IFERROR(G14,0)+IFERROR(H14,0) -> 1610 | DD14: =ABS(IFERROR(T14,0)) -> 360.962 | DE14: =ABS(IFERROR(P14,0)+IFERROR(Q14,0)) -> 8.626 | DF14: =ABS(IFERROR(AH14,0))+ABS(IFERROR(AK14,0))+IFERROR(W14,0) -> 53.1 | DG14: =IFERROR(M14,0)+IFERROR(N14,0)+IFERROR(O14,0)+IFERROR(P14,0) -> 179.688 | DH14: 1187.312
A15: 8741339872 | B15: 10741334937 | C15: 45938.423 | D15: 45942.46 | E15: TNBYCLST96884745 | F15: 1421 | G15: 0 | H15: 1421 | I15: 2250 | J15: 658 | K15: Inter-State | L15: 5 | M15: 67.67 | N15: 0 | O15: 0 | P15: 6.767 | Q15: 1.353 | R15: 27.14 | S15: 385.659 | T15: -385.659 | U15: -393.779 | V15: -53.1 | W15: 0 | X15: 45 | Y15: 0 | Z15: 8.1 | AA15: 1 | AB15: NATIONAL | AC15: 1592 | AD15: 974.121 | AE15: 974.121 | AF15: 0 | AG15: -393.779 | AH15: -53.1 | AI15: 1421 | AJ15: 0 | AL15: 0 | AM15: 45957 | AN15: 45957 | AO15: 45957 | AP15: 0 | AQ15: 1353.33 | AR15: 5 | AS15: 0 | AT15: 0 | AU15: 0.5 | AV15: 0 | AW15: 0 | AX15: 0.1 | AY15: Tiny Baby | AZ15: Clothing Set | BA15: 27.14 | BB15: 0 | BC15: 385.659 | BD15: -385.659 | BE15: 0 | BF15: 0 | BG15: 0 | BH15: 658 | BI15: 1.35333 | BL15: 0 | BM15: 0 | BN15: 0 | BO15: 0 | BP15: 0 | BS15: 3302034f-f15d-4331-b7e5-a128b83e4254 | BT15: 6.767 | BU15: 0 | BV15: 1.353 | BW15: 0 | BX15: 0 | BY15: 0 | BZ15: 0 | CA15: 0 | CB15: 0 | CC15: 0 | CD15: 0 | CE15: 0 | CF15: 0 | CG15: 0 | CH15: 0 | CI15: 0 | CJ15: 974.121 | CK15: 0 | CL15: 0 | CM15: 0 | CN15: 0 | CO15: 0 | CP15: 0 | CQ15: 0 | CR15: 0 | CS15: 0 | CT15: 0 | CU15: 0 | CV15: 0 | CW15: 0 | CX15: 0 | CY15: 0 | CZ15: 0 | DA15: 0 | DB15: 0 | DC15: =IFERROR(G15,0)+IFERROR(H15,0) -> 1421 | DD15: =ABS(IFERROR(T15,0)) -> 385.659 | DE15: =ABS(IFERROR(P15,0)+IFERROR(Q15,0)) -> 8.12 | DF15: =ABS(IFERROR(AH15,0))+ABS(IFERROR(AK15,0))+IFERROR(W15,0) -> 53.1 | DG15: =IFERROR(M15,0)+IFERROR(N15,0)+IFERROR(O15,0)+IFERROR(P15,0) -> 74.437 | DH15: 974.121
A16: 8720752290 | B16: 10720697209 | C16: 45930.615 | D16: 45936.703 | E16: TIKILHNC103613408 | F16: 2944.01 | G16: 0 | H16: 2944 | I16: 4500 | J16: 1350 | K16: Inter-State | L16: 18 | M16: 449.09 | N16: 0 | O16: 0 | P16: 12.475 | Q16: 2.495 | R16: 24.78 | S16: 729.523 | T16: -729.523 | U16: -744.493 | V16: -71.98 | W16: 0 | X16: 61 | Y16: 0 | Z16: 10.98 | AA16: 1 | AB16: ZONAL | AC16: 3150 | AD16: 2127.527 | AE16: 2127.527 | AF16: 0 | AG16: -744.493 | AH16: -71.98 | AI16: 2944 | AJ16: 0 | AL16: 0 | AM16: 45953 | AN16: 45953 | AO16: 45953 | AP16: 0 | AQ16: 2494.92 | AR16: 18 | AS16: 0 | AT16: 0 | AU16: 0.5 | AV16: 0 | AW16: 0 | AX16: 0.1 | AY16: Tiny Kingdom | AZ16: Lehenga Choli | BA16: 24.78 | BB16: 0 | BC16: 729.523 | BD16: -729.523 | BE16: 0 | BF16: 0 | BG16: 0 | BH16: 1350 | BI16: 2.49492 | BL16: 0 | BM16: 0 | BN16: 0 | BO16: 0 | BP16: 0 | BS16: ba6710b6-1db2-40c5-898c-0e75736adc14 | BT16: 12.475 | BU16: 0 | BV16: 2.495 | BW16: 0 | BX16: 0 | BY16: 0 | BZ16: 0 | CA16: 0 | CB16: 0 | CC16: 0 | CD16: 0 | CE16: 0 | CF16: 0 | CG16: 0 | CH16: 2127.527 | CI16: 0 | CJ16: 0 | CK16: 0 | CL16: 0 | CM16: 0 | CN16: 0 | CO16: 0 | CP16: 0 | CQ16: 0 | CR16: 0 | CS16: 0 | CT16: 0 | CU16: 0 | CV16: 0 | CW16: 0 | CX16: 0 | CY16: 0 | CZ16: 0 | DA16: 0 | DB16: 0 | DC16: =IFERROR(G16,0)+IFERROR(H16,0) -> 2944 | DD16: =ABS(IFERROR(T16,0)) -> 729.523 | DE16: =ABS(IFERROR(P16,0)+IFERROR(Q16,0)) -> 14.97 | DF16: =ABS(IFERROR(AH16,0))+ABS(IFERROR(AK16,0))+IFERROR(W16,0) -> 71.98 | DG16: =IFERROR(M16,0)+IFERROR(N16,0)+IFERROR(O16,0)+IFERROR(P16,0) -> 461.565 | DH16: 2127.527
A17: 8657021789 | B17: 10656945910 | C17: 45909.456 | D17: 45919.637 | E17: TNBYDRSS60563528 | F17: 706 | G17: 0 | H17: 706 | I17: 2000 | J17: 1200 | K17: Inter-State | L17: 5 | M17: 33.62 | N17: 0 | O17: 0 | P17: 3.362 | Q17: 0.672 | R17: 29.5 | S17: 208.27 | T17: -208.27 | U17: -212.304 | V17: -31.86 | W17: 0 | X17: 27 | Y17: 0 | Z17: 4.86 | AA17: 1 | AB17: NATIONAL | AC17: 800 | AD17: 461.836 | AE17: 461.836 | AF17: 0 | AG17: -212.304 | AH17: -31.86 | AI17: 706 | AJ17: 0 | AL17: 0 | AM17: 45933 | AN17: 45933 | AO17: 45933 | AP17: 0 | AQ17: 672.38 | AR17: 5 | AS17: 0 | AT17: 0 | AU17: 0.5 | AV17: 0 | AW17: 0 | AX17: 0.1 | AY17: Tiny Baby | AZ17: Dresses | BA17: 29.5 | BB17: 0 | BC17: 208.27 | BD17: -208.27 | BE17: 0 | BF17: 0 | BG17: 0 | BH17: 1200 | BI17: 0.67238 | BL17: 0 | BM17: 0 | BN17: 0 | BO17: 0 | BP17: 0 | BS17: d591f506-0e15-4a76-a50a-5e05cc4f7e7b | BT17: 3.362 | BU17: 0 | BV17: 0.672 | BW17: 0 | BX17: 461.836 | BY17: 0 | BZ17: 0 | CA17: 0 | CB17: 0 | CC17: 0 | CD17: 0 | CE17: 0 | CF17: 0 | CG17: 0 | CH17: 0 | CI17: 0 | CJ17: 0 | CK17: 0 | CL17: 0 | CM17: 0 | CN17: 0 | CO17: 0 | CP17: 0 | CQ17: 0 | CR17: 0 | CS17: 0 | CT17: 0 | CU17: 0 | CV17: 0 | CW17: 0 | CX17: 0 | CY17: 0 | CZ17: 0 | DA17: 0 | DB17: 0 | DC17: =IFERROR(G17,0)+IFERROR(H17,0) -> 706 | DD17: =ABS(IFERROR(T17,0)) -> 208.27 | DE17: =ABS(IFERROR(P17,0)+IFERROR(Q17,0)) -> 4.034 | DF17: =ABS(IFERROR(AH17,0))+ABS(IFERROR(AK17,0))+IFERROR(W17,0) -> 31.86 | DG17: =IFERROR(M17,0)+IFERROR(N17,0)+IFERROR(O17,0)+IFERROR(P17,0) -> 36.982 | DH17: 461.836
A18: 8737192003 | B18: 10737169109 | C18: 45936.455 | D18: 45942.791 | E18: BETYDRSS67133154 | F18: 391 | G18: 0 | H18: 391 | I18: 2750 | J18: 2300 | K18: Inter-State | L18: 5 | M18: 18.62 | N18: 0 | O18: 0 | P18: 1.862 | Q18: 0.372 | R18: 2.36 | S18: 9.228 | T18: -9.228 | U18: -11.462 | V18: -31.86 | W18: 0 | X18: 27 | Y18: 0 | Z18: 4.86 | AA18: 1 | AB18: NATIONAL | AC18: 450 | AD18: 347.678 | AE18: 347.678 | AF18: 0 | AG18: -11.462 | AH18: -31.86 | AI18: 391 | AJ18: 0 | AL18: 0 | AM18: 45957 | AN18: 45957 | AO18: 45957 | AP18: 0 | AQ18: 372.38 | AR18: 5 | AS18: 0 | AT18: 0 | AU18: 0.5 | AV18: 0 | AW18: 0 | AX18: 0.1 | AY18: BETTY | AZ18: Dresses | BA18: 2.36 | BB18: 0 | BC18: 9.228 | BD18: -9.228 | BE18: 0 | BF18: 0 | BG18: 0 | BH18: 2300 | BI18: 0.37238 | BL18: 0 | BM18: 0 | BN18: 0 | BO18: 0 | BP18: 0 | BS18: 63c321aa-b3a4-4801-8fdf-df8a1e196647 | BT18: 1.862 | BU18: 0 | BV18: 0.372 | BW18: 0 | BX18: 0 | BY18: 0 | BZ18: 0 | CA18: 0 | CB18: 0 | CC18: 0 | CD18: 0 | CE18: 0 | CF18: 0 | CG18: 0 | CH18: 0 | CI18: 0 | CJ18: 347.678 | CK18: 0 | CL18: 0 | CM18: 0 | CN18: 0 | CO18: 0 | CP18: 0 | CQ18: 0 | CR18: 0 | CS18: 0 | CT18: 0 | CU18: 0 | CV18: 0 | CW18: 0 | CX18: 0 | CY18: 0 | CZ18: 0 | DA18: 0 | DB18: 0 | DC18: =IFERROR(G18,0)+IFERROR(H18,0) -> 391 | DD18: =ABS(IFERROR(T18,0)) -> 9.228 | DE18: =ABS(IFERROR(P18,0)+IFERROR(Q18,0)) -> 2.234 | DF18: =ABS(IFERROR(AH18,0))+ABS(IFERROR(AK18,0))+IFERROR(W18,0) -> 31.86 | DG18: =IFERROR(M18,0)+IFERROR(N18,0)+IFERROR(O18,0)+IFERROR(P18,0) -> 20.482 | DH18: 347.678
A19: 8715339734 | B19: 10715279507 | C19: 45929.449 | D19: 45935.676 | E19: BETYDRSS100320371 | F19: 3470 | G19: 0 | H19: 3470 | I19: 5000 | J19: 1324 | K19: Inter-State | L19: 18 | M19: 529.32 | N19: 0 | O19: 0 | P19: 14.703 | Q19: 2.941 | R19: 31.86 | S19: 1105.542 | T19: -1105.542 | U19: -1123.186 | V19: -71.98 | W19: 0 | X19: 61 | Y19: 0 | Z19: 10.98 | AA19: 1 | AB19: NATIONAL | AC19: 3676 | AD19: 2274.834 | AE19: 2274.834 | AF19: 0 | AG19: -1123.186 | AH19: -71.98 | AI19: 3470 | AJ19: 0 | AL19: 0 | AM19: 45953 | AN19: 45953 | AO19: 45953 | AP19: 0 | AQ19: 2940.68 | AR19: 18 | AS19: 0 | AT19: 0 | AU19: 0.5 | AV19: 0 | AW19: 0 | AX19: 0.1 | AY19: BETTY | AZ19: Dresses | BA19: 31.86 | BB19: 0 | BC19: 1105.542 | BD19: -1105.542 | BE19: 0 | BF19: 0 | BG19: 0 | BH19: 1324 | BI19: 2.94068 | BL19: 0 | BM19: 0 | BN19: 0 | BO19: 0 | BP19: 0 | BS19: de0e3b21-d9fd-4455-877e-a1b99f2775bd | BT19: 14.703 | BU19: 0 | BV19: 2.941 | BW19: 0 | BX19: 0 | BY19: 0 | BZ19: 0 | CA19: 0 | CB19: 0 | CC19: 0 | CD19: 0 | CE19: 0 | CF19: 0 | CG19: 0 | CH19: 2274.834 | CI19: 0 | CJ19: 0 | CK19: 0 | CL19: 0 | CM19: 0 | CN19: 0 | CO19: 0 | CP19: 0 | CQ19: 0 | CR19: 0 | CS19: 0 | CT19: 0 | CU19: 0 | CV19: 0 | CW19: 0 | CX19: 0 | CY19: 0 | CZ19: 0 | DA19: 0 | DB19: 0 | DC19: =IFERROR(G19,0)+IFERROR(H19,0) -> 3470 | DD19: =ABS(IFERROR(T19,0)) -> 1105.542 | DE19: =ABS(IFERROR(P19,0)+IFERROR(Q19,0)) -> 17.644 | DF19: =ABS(IFERROR(AH19,0))+ABS(IFERROR(AK19,0))+IFERROR(W19,0) -> 71.98 | DG19: =IFERROR(M19,0)+IFERROR(N19,0)+IFERROR(O19,0)+IFERROR(P19,0) -> 544.023 | DH19: 2274.834
A20: 8697412249 | B20: 10697341267 | C20: 45922.78 | D20: 45927.78 | E20: TIKIDRSS113039558 | F20: 3109.01 | G20: 0 | H20: 3109 | I20: 3500 | J20: 185 | K20: Inter-State | L20: 18 | M20: 474.26 | N20: 0 | O20: 0 | P20: 13.174 | Q20: 2.635 | R20: 21.24 | S20: 660.352 | T20: -660.352 | U20: -676.161 | V20: -71.98 | W20: 0 | X20: 61 | Y20: 0 | Z20: 10.98 | AA20: 1 | AB20: NATIONAL | AC20: 3315 | AD20: 2360.859 | AE20: 2360.859 | AF20: 0 | AG20: -676.161 | AH20: -71.98 | AI20: 3109 | AJ20: 0 | AL20: 0 | AM20: 45943 | AN20: 45943 | AO20: 45943 | AP20: 0 | AQ20: 2634.75 | AR20: 18 | AS20: 0 | AT20: 0 | AU20: 0.5 | AV20: 0 | AW20: 0 | AX20: 0.1 | AY20: Tiny Kingdom | AZ20: Dresses | BA20: 21.24 | BB20: 0 | BC20: 660.352 | BD20: -660.352 | BE20: 0 | BF20: 0 | BG20: 0 | BH20: 185 | BI20: 2.63475 | BL20: 0 | BM20: 0 | BN20: 0 | BO20: 0 | BP20: 0 | BS20: 88ea3330-ee26-44ae-bbd4-56ef53849b2c | BT20: 13.174 | BU20: 0 | BV20: 2.635 | BW20: 0 | BX20: 0 | BY20: 0 | BZ20: 0 | CA20: 0 | CB20: 0 | CC20: 2360.859 | CD20: 0 | CE20: 0 | CF20: 0 | CG20: 0 | CH20: 0 | CI20: 0 | CJ20: 0 | CK20: 0 | CL20: 0 | CM20: 0 | CN20: 0 | CO20: 0 | CP20: 0 | CQ20: 0 | CR20: 0 | CS20: 0 | CT20: 0 | CU20: 0 | CV20: 0 | CW20: 0 | CX20: 0 | CY20: 0 | CZ20: 0 | DA20: 0 | DB20: 0 | DC20: =IFERROR(G20,0)+IFERROR(H20,0) -> 3109 | DD20: =ABS(IFERROR(T20,0)) -> 660.352 | DE20: =ABS(IFERROR(P20,0)+IFERROR(Q20,0)) -> 15.809 | DF20: =ABS(IFERROR(AH20,0))+ABS(IFERROR(AK20,0))+IFERROR(W20,0) -> 71.98 | DG20: =IFERROR(M20,0)+IFERROR(N20,0)+IFERROR(O20,0)+IFERROR(P20,0) -> 487.434 | DH20: 2360.859
... A22: 8715259067 | B22: 10715198840 | C22: 45929.449 | D22: 45933.717 | E22: BETYDRSS81635448 | F22: 2150 | G22: 0 | H22: 2150 | I22: 5000 | J22: 2644 | K22: Inter-State | L22: 5 | M22: 102.38 | N22: 0 | O22: 0 | P22: 10.238 | Q22: 2.048 | R22: 31.86 | S22: 684.99 | T22: -684.99 | U22: -697.276 | V22: -71.98 | W22: 0 | X22: 61 | Y22: 0 | Z22: 10.98 | AA22: 1 | AB22: NATIONAL | AC22: 2356 | AD22: 1380.744 | AE22: 1380.744 | AF22: 0 | AG22: -697.276 | AH22: -71.98 | AI22: 2150 | AJ22: 0 | AL22: 0 | AM22: 45947 | AN22: 45947 | AO22: 45947 | AP22: 0 | AQ22: 2047.62 | AR22: 5 | AS22: 0 | AT22: 0 | AU22: 0.5 | AV22: 0 | AW22: 0 | AX22: 0.1 | AY22: BETTY | AZ22: Dresses | BA22: 31.86 | BB22: 0 | BC22: 684.99 | BD22: -684.99 | BE22: 0 | BF22: 0 | BG22: 0 | BH22: 2644 | BI22: 2.04762 | BL22: 0 | BM22: 0 | BN22: 0 | BO22: 0 | BP22: 0 | BS22: 23383067-8dba-40c1-a010-f4bd43daabf1 | BT22: 10.238 | BU22: 0 | BV22: 2.048 | BW22: 0 | BX22: 0 | BY22: 0 | BZ22: 0 | CA22: 0 | CB22: 0 | CC22: 0 | CD22: 0 | CE22: 0 | CF22: 0 | CG22: 1380.744 | CH22: 0 | CI22: 0 | CJ22: 0 | CK22: 0 | CL22: 0 | CM22: 0 | CN22: 0 | CO22: 0 | CP22: 0 | CQ22: 0 | CR22: 0 | CS22: 0 | CT22: 0 | CU22: 0 | CV22: 0 | CW22: 0 | CX22: 0 | CY22: 0 | CZ22: 0 | DA22: 0 | DB22: 0 | DC22: =IFERROR(G22,0)+IFERROR(H22,0) -> 2150 | DD22: =ABS(IFERROR(T22,0)) -> 684.99 | DE22: =ABS(IFERROR(P22,0)+IFERROR(Q22,0)) -> 12.286 | DF22: =ABS(IFERROR(AH22,0))+ABS(IFERROR(AK22,0))+IFERROR(W22,0) -> 71.98 | DG22: =IFERROR(M22,0)+IFERROR(N22,0)+IFERROR(O22,0)+IFERROR(P22,0) -> 112.618 | DH22: 1380.744
A23: 8742176123 | B23: 10742175834 | C23: 45938.519 | D23: 45942.705 | E23: TNBYCLST106795158 | F23: 2198 | G23: 2198 | H23: 0 | I23: 3000 | J23: 596 | K23: Inter-State | L23: 5 | M23: 104.67 | N23: 0 | O23: 0 | P23: 10.467 | Q23: 2.093 | R23: 25.96 | S23: 570.601 | T23: -570.601 | U23: -583.161 | V23: -71.98 | W23: 0 | X23: 61 | Y23: 0 | Z23: 10.98 | AA23: 1 | AB23: NATIONAL | AC23: 2404 | AD23: 1542.859 | AE23: 1542.859 | AF23: 0 | AG23: 0 | AI23: 0 | AJ23: -583.161 | AK23: -71.98 | AL23: 2198 | AP23: 0 | AQ23: 2093.33 | AR23: 5 | AS23: 0 | AT23: 0 | AU23: 0.5 | AV23: 0 | AW23: 0 | AX23: 0.1 | AY23: Tiny Baby | AZ23: Clothing Set | BC23: 0 | BD23: 0 | BE23: 0 | BF23: 0 | BG23: 0 | BJ23: 25.96 | BK23: 0 | BL23: 570.601 | BM23: -570.601 | BN23: 0 | BO23: 0 | BP23: 0 | BQ23: 596 | BR23: 2.09333 | BS23: f2dce908-898d-4405-9bd8-3b51ef3ee483 | BT23: 0 | BU23: 10.467 | BV23: 0 | BW23: 2.093 | BX23: 0 | BY23: 0 | BZ23: 0 | CA23: 0 | CB23: 0 | CC23: 0 | CD23: 0 | CE23: 0 | CF23: 0 | CG23: 0 | CH23: 0 | CI23: 0 | CJ23: 1542.859 | CK23: 0 | CL23: 0 | CM23: 0 | CN23: 0 | CO23: 0 | CP23: 0 | CQ23: 0 | CR23: 0 | CS23: 0 | CT23: 0 | CU23: 0 | CV23: 0 | CW23: 0 | CX23: 0 | CY23: 0 | CZ23: 0 | DA23: 0 | DB23: 0 | DC23: =IFERROR(G23,0)+IFERROR(H23,0) -> 2198 | DD23: =ABS(IFERROR(T23,0)) -> 570.601 | DE23: =ABS(IFERROR(P23,0)+IFERROR(Q23,0)) -> 12.56 | DF23: =ABS(IFERROR(AH23,0))+ABS(IFERROR(AK23,0))+IFERROR(W23,0) -> 71.98 | DG23: =IFERROR(M23,0)+IFERROR(N23,0)+IFERROR(O23,0)+IFERROR(P23,0) -> 115.137 | DH23: 1542.859
A24: 8682082418 | B24: 10682009123 | C24: 45919.525 | D24: 45924.545 | E24: BETYLHNC96459192 | F24: 1694 | G24: 1694 | H24: 0 | I24: 4000 | J24: 2000 | K24: Inter-State | L24: 12 | M24: 181.5 | N24: 0 | O24: 0 | P24: 7.562 | Q24: 1.512 | R24: 29.5 | S24: 499.73 | T24: -499.73 | U24: -508.804 | V24: -53.1 | W24: 0 | X24: 45 | Y24: 0 | Z24: 8.1 | AA24: 1 | AB24: NATIONAL | AC24: 1900 | AD24: 1132.096 | AE24: 1132.096 | AF24: 0 | AG24: 0 | AI24: 0 | AJ24: -508.804 | AK24: -53.1 | AL24: 1694 | AP24: 0 | AQ24: 1512.5 | AR24: 12 | AS24: 0 | AT24: 0 | AU24: 0.5 | AV24: 0 | AW24: 0 | AX24: 0.1 | AY24: BETTY | AZ24: Lehenga Choli | BC24: 0 | BD24: 0 | BE24: 0 | BF24: 0 | BG24: 0 | BJ24: 29.5 | BK24: 0 | BL24: 499.73 | BM24: -499.73 | BN24: 0 | BO24: 0 | BP24: 0 | BQ24: 2000 | BR24: 1.5125 | BS24: ed104123-a92e-42f9-9f20-ee6a6406ea0d | BT24: 0 | BU24: 7.562 | BV24: 0 | BW24: 1.512 | BX24: 0 | BY24: 0 | BZ24: 1132.096 | CA24: 0 | CB24: 0 | CC24: 0 | CD24: 0 | CE24: 0 | CF24: 0 | CG24: 0 | CH24: 0 | CI24: 0 | CJ24: 0 | CK24: 0 | CL24: 0 | CM24: 0 | CN24: 0 | CO24: 0 | CP24: 0 | CQ24: 0 | CR24: 0 | CS24: 0 | CT24: 0 | CU24: 0 | CV24: 0 | CW24: 0 | CX24: 0 | CY24: 0 | CZ24: 0 | DA24: 0 | DB24: 0 | DC24: =IFERROR(G24,0)+IFERROR(H24,0) -> 1694 | DD24: =ABS(IFERROR(T24,0)) -> 499.73 | DE24: =ABS(IFERROR(P24,0)+IFERROR(Q24,0)) -> 9.074 | DF24: =ABS(IFERROR(AH24,0))+ABS(IFERROR(AK24,0))+IFERROR(W24,0) -> 53.1 | DG24: =IFERROR(M24,0)+IFERROR(N24,0)+IFERROR(O24,0)+IFERROR(P24,0) -> 189.062 | DH24: 1132.096
A25: 8747034027 | B25: 10747055015 | C25: 45941.44 | D25: 45946.79 | E25: TIKILHNC115963256 | F25: 3564 | G25: 0 | H25: 3564 | I25: 4000 | J25: 230 | K25: Inter-State | L25: 18 | M25: 543.66 | N25: 0 | O25: 0 | P25: 15.102 | Q25: 3.02 | R25: 24.78 | S25: 883.159 | T25: -883.159 | U25: -901.281 | V25: -71.98 | W25: 0 | X25: 61 | Y25: 0 | Z25: 10.98 | AA25: 1 | AB25: NATIONAL | AC25: 3770 | AD25: 2590.739 | AE25: 2590.739 | AF25: 0 | AG25: -901.281 | AH25: -71.98 | AI25: 3564 | AJ25: 0 | AL25: 0 | AM25: 45960 | AN25: 45960 | AO25: 45960 | AP25: 0 | AQ25: 3020.34 | AR25: 18 | AS25: 0 | AT25: 0 | AU25: 0.5 | AV25: 0 | AW25: 0 | AX25: 0.1 | AY25: Tiny Kingdom | AZ25: Lehenga Choli | BA25: 24.78 | BB25: 0 | BC25: 883.159 | BD25: -883.159 | BE25: 0 | BF25: 0 | BG25: 0 | BH25: 230 | BI25: 3.02034 | BL25: 0 | BM25: 0 | BN25: 0 | BO25: 0 | BP25: 0 | BS25: 70eae005-72af-4558-b677-ff3604b0322e | BT25: 15.102 | BU25: 0 | BV25: 3.02 | BW25: 0 | BX25: 0 | BY25: 0 | BZ25: 0 | CA25: 0 | CB25: 0 | CC25: 0 | CD25: 0 | CE25: 0 | CF25: 0 | CG25: 0 | CH25: 0 | CI25: 0 | CJ25: 0 | CK25: 0 | CL25: 0 | CM25: 2590.739 | CN25: 0 | CO25: 0 | CP25: 0 | CQ25: 0 | CR25: 0 | CS25: 0 | CT25: 0 | CU25: 0 | CV25: 0 | CW25: 0 | CX25: 0 | CY25: 0 | CZ25: 0 | DA25: 0 | DB25: 0 | DC25: =IFERROR(G25,0)+IFERROR(H25,0) -> 3564 | DD25: =ABS(IFERROR(T25,0)) -> 883.159 | DE25: =ABS(IFERROR(P25,0)+IFERROR(Q25,0)) -> 18.122 | DF25: =ABS(IFERROR(AH25,0))+ABS(IFERROR(AK25,0))+IFERROR(W25,0) -> 71.98 | DG25: =IFERROR(M25,0)+IFERROR(N25,0)+IFERROR(O25,0)+IFERROR(P25,0) -> 558.762 | DH25: 2590.739
A26: 8737583490 | B26: 10737560594 | C26: 45936.455 | D26: 45940.683 | E26: BETYDRSS74936962 | F26: 1644 | G26: 0 | H26: 1644 | I26: 3850 | J26: 2035 | K26: Inter-State | L26: 5 | M26: 78.29 | N26: 0 | O26: 0 | P26: 7.829 | Q26: 1.566 | R26: 33.04 | S26: 543.178 | T26: -543.178 | U26: -552.573 | V26: -53.1 | W26: 0 | X26: 45 | Y26: 0 | Z26: 8.1 | AA26: 1 | AB26: NATIONAL | AC26: 1815 | AD26: 1038.327 | AE26: 1038.327 | AF26: 0 | AG26: -552.573 | AH26: -53.1 | AI26: 1644 | AJ26: 0 | AL26: 0 | AM26: 45954 | AN26: 45954 | AO26: 45954 | AP26: 0 | AQ26: 1565.71 | AR26: 5 | AS26: 0 | AT26: 0 | AU26: 0.5 | AV26: 0 | AW26: 0 | AX26: 0.1 | AY26: BETTY | AZ26: Dresses | BA26: 33.04 | BB26: 0 | BC26: 543.178 | BD26: -543.178 | BE26: 0 | BF26: 0 | BG26: 0 | BH26: 2035 | BI26: 1.56571 | BL26: 0 | BM26: 0 | BN26: 0 | BO26: 0 | BP26: 0 | BS26: 4d6c19b3-e810-4b37-acec-4ec133be471d | BT26: 7.829 | BU26: 0 | BV26: 1.566 | BW26: 0 | BX26: 0 | BY26: 0 | BZ26: 0 | CA26: 0 | CB26: 0 | CC26: 0 | CD26: 0 | CE26: 0 | CF26: 0 | CG26: 0 | CH26: 0 | CI26: 1038.327 | CJ26: 0 | CK26: 0 | CL26: 0 | CM26: 0 | CN26: 0 | CO26: 0 | CP26: 0 | CQ26: 0 | CR26: 0 | CS26: 0 | CT26: 0 | CU26: 0 | CV26: 0 | CW26: 0 | CX26: 0 | CY26: 0 | CZ26: 0 | DA26: 0 | DB26: 0 | DC26: =IFERROR(G26,0)+IFERROR(H26,0) -> 1644 | DD26: =ABS(IFERROR(T26,0)) -> 543.178 | DE26: =ABS(IFERROR(P26,0)+IFERROR(Q26,0)) -> 9.395 | DF26: =ABS(IFERROR(AH26,0))+ABS(IFERROR(AK26,0))+IFERROR(W26,0) -> 53.1 | DG26: =IFERROR(M26,0)+IFERROR(N26,0)+IFERROR(O26,0)+IFERROR(P26,0) -> 86.119 | DH26: 1038.327
A27: 8739466534 | B27: 10739452262 | C27: 45937.468 | D27: 45943.627 | E27: TIKILHNC106661968 | F27: 4445 | G27: 4445 | H27: 0 | I27: 5000 | J27: 349 | K27: Inter-State | L27: 18 | M27: 678.05 | N27: 0 | O27: 0 | P27: 18.835 | Q27: 3.767 | R27: 24.78 | S27: 1101.471 | T27: -1101.471 | U27: -1124.073 | V27: -71.98 | W27: 0 | X27: 61 | Y27: 0 | Z27: 10.98 | AA27: 1 | AB27: NATIONAL | AC27: 4651 | AD27: 3248.947 | AE27: 3248.947 | AF27: 0 | AG27: 0 | AI27: 0 | AJ27: -1124.073 | AK27: -71.98 | AL27: 4445 | AP27: 0 | AQ27: 3766.95 | AR27: 18 | AS27: 0 | AT27: 0 | AU27: 0.5 | AV27: 0 | AW27: 0 | AX27: 0.1 | AY27: Tiny Kingdom | AZ27: Lehenga Choli | BC27: 0 | BD27: 0 | BE27: 0 | BF27: 0 | BG27: 0 | BJ27: 24.78 | BK27: 0 | BL27: 1101.471 | BM27: -1101.471 | BN27: 0 | BO27: 0 | BP27: 0 | BQ27: 349 | BR27: 3.76695 | BS27: 9eefd143-11dc-4cde-8651-e07aad739bc9 | BT27: 0 | BU27: 18.835 | BV27: 0 | BW27: 3.767 | BX27: 0 | BY27: 0 | BZ27: 0 | CA27: 0 | CB27: 0 | CC27: 0 | CD27: 0 | CE27: 0 | CF27: 0 | CG27: 0 | CH27: 0 | CI27: 0 | CJ27: 3248.947 | CK27: 0 | CL27: 0 | CM27: 0 | CN27: 0 | CO27: 0 | CP27: 0 | CQ27: 0 | CR27: 0 | CS27: 0 | CT27: 0 | CU27: 0 | CV27: 0 | CW27: 0 | CX27: 0 | CY27: 0 | CZ27: 0 | DA27: 0 | DB27: 0 | DC27: =IFERROR(G27,0)+IFERROR(H27,0) -> 4445 | DD27: =ABS(IFERROR(T27,0)) -> 1101.471 | DE27: =ABS(IFERROR(P27,0)+IFERROR(Q27,0)) -> 22.602 | DF27: =ABS(IFERROR(AH27,0))+ABS(IFERROR(AK27,0))+IFERROR(W27,0) -> 71.98 | DG27: =IFERROR(M27,0)+IFERROR(N27,0)+IFERROR(O27,0)+IFERROR(P27,0) -> 696.885 | DH27: 3248.947
A28: 8735054496 | B28: 10735026688 | C28: 45935.461 | D28: 45938.422 | E28: TIKILHNC115963235 | F28: 3169 | G28: 0 | H28: 3169 | I28: 3750 | J28: 375 | K28: Inter-State | L28: 18 | M28: 483.41 | N28: 0 | O28: 0 | P28: 13.428 | Q28: 2.686 | R28: 24.78 | S28: 785.278 | T28: -785.278 | U28: -801.392 | V28: -71.98 | W28: 0 | X28: 61 | Y28: 0 | Z28: 10.98 | AA28: 1 | AB28: ZONAL | AC28: 3375 | AD28: 2295.628 | AE28: 2295.628 | AF28: 0 | AG28: -801.392 | AH28: -71.98 | AI28: 3169 | AJ28: 0 | AL28: 0 | AM28: 45953 | AN28: 45953 | AO28: 45953 | AP28: 0 | AQ28: 2685.59 | AR28: 18 | AS28: 0 | AT28: 0 | AU28: 0.5 | AV28: 0 | AW28: 0 | AX28: 0.1 | AY28: Tiny Kingdom | AZ28: Lehenga Choli | BA28: 24.78 | BB28: 0 | BC28: 785.278 | BD28: -785.278 | BE28: 0 | BF28: 0 | BG28: 0 | BH28: 375 | BI28: 2.68559 | BL28: 0 | BM28: 0 | BN28: 0 | BO28: 0 | BP28: 0 | BS28: b5836731-4725-4be0-981d-cc011944ecce | BT28: 13.428 | BU28: 0 | BV28: 2.686 | BW28: 0 | BX28: 0 | BY28: 0 | BZ28: 0 | CA28: 0 | CB28: 0 | CC28: 0 | CD28: 0 | CE28: 0 | CF28: 0 | CG28: 0 | CH28: 2295.628 | CI28: 0 | CJ28: 0 | CK28: 0 | CL28: 0 | CM28: 0 | CN28: 0 | CO28: 0 | CP28: 0 | CQ28: 0 | CR28: 0 | CS28: 0 | CT28: 0 | CU28: 0 | CV28: 0 | CW28: 0 | CX28: 0 | CY28: 0 | CZ28: 0 | DA28: 0 | DB28: 0 | DC28: =IFERROR(G28,0)+IFERROR(H28,0) -> 3169 | DD28: =ABS(IFERROR(T28,0)) -> 785.278 | DE28: =ABS(IFERROR(P28,0)+IFERROR(Q28,0)) -> 16.114 | DF28: =ABS(IFERROR(AH28,0))+ABS(IFERROR(AK28,0))+IFERROR(W28,0) -> 71.98 | DG28: =IFERROR(M28,0)+IFERROR(N28,0)+IFERROR(O28,0)+IFERROR(P28,0) -> 496.838 | DH28: 2295.628
A29: 8675097215 | B29: 10675021810 | C29: 45916.56 | D29: 45919.669 | E29: TIKILHNC112303900 | F29: 2794 | G29: 0 | H29: 2794 | I29: 3750 | J29: 750 | K29: Inter-State | L29: 12 | M29: 299.36 | N29: 0 | O29: 0 | P29: 12.473 | Q29: 2.495 | R29: 24.78 | S29: 692.353 | T29: -692.353 | U29: -707.321 | V29: -71.98 | W29: 0 | X29: 61 | Y29: 0 | Z29: 10.98 | AA29: 1 | AB29: ZONAL | AC29: 3000 | AD29: 2014.699 | AE29: 2014.699 | AF29: 0 | AG29: -707.321 | AH29: -71.98 | AI29: 2794 | AJ29: 0 | AL29: 0 | AM29: 45933 | AN29: 45933 | AO29: 45933 | AP29: 0 | AQ29: 2494.64 | AR29: 12 | AS29: 0 | AT29: 0 | AU29: 0.5 | AV29: 0 | AW29: 0 | AX29: 0.1 | AY29: Tiny Kingdom | AZ29: Lehenga Choli | BA29: 24.78 | BB29: 0 | BC29: 692.353 | BD29: -692.353 | BE29: 0 | BF29: 0 | BG29: 0 | BH29: 750 | BI29: 2.49464 | BL29: 0 | BM29: 0 | BN29: 0 | BO29: 0 | BP29: 0 | BS29: d2796cf4-07b6-4a5a-b022-7cf9338a29b1 | BT29: 12.473 | BU29: 0 | BV29: 2.495 | BW29: 0 | BX29: 2014.699 | BY29: 0 | BZ29: 0 | CA29: 0 | CB29: 0 | CC29: 0 | CD29: 0 | CE29: 0 | CF29: 0 | CG29: 0 | CH29: 0 | CI29: 0 | CJ29: 0 | CK29: 0 | CL29: 0 | CM29: 0 | CN29: 0 | CO29: 0 | CP29: 0 | CQ29: 0 | CR29: 0 | CS29: 0 | CT29: 0 | CU29: 0 | CV29: 0 | CW29: 0 | CX29: 0 | CY29: 0 | CZ29: 0 | DA29: 0 | DB29: 0 | DC29: =IFERROR(G29,0)+IFERROR(H29,0) -> 2794 | DD29: =ABS(IFERROR(T29,0)) -> 692.353 | DE29: =ABS(IFERROR(P29,0)+IFERROR(Q29,0)) -> 14.968 | DF29: =ABS(IFERROR(AH29,0))+ABS(IFERROR(AK29,0))+IFERROR(W29,0) -> 71.98 | DG29: =IFERROR(M29,0)+IFERROR(N29,0)+IFERROR(O29,0)+IFERROR(P29,0) -> 311.833 | DH29: 2014.699
A30: 8599978899 | B30: 10599905055 | C30: 45873.626 | D30: 45876.476 | E30: TIKILHNC99304399 | F30: 1179 | G30: 1179 | H30: 0 | I30: 4500 | J30: 3150 | K30: Inter-State | L30: 12 | M30: 126.32 | N30: 0 | O30: 0 | P30: 5.263 | Q30: 1.053 | R30: 24.78 | S30: 292.156 | T30: -292.156 | U30: -298.472 | V30: -53.1 | W30: 0 | X30: 45 | Y30: 0 | Z30: 8.1 | AA30: 1 | AB30: ZONAL | AC30: 1350 | AD30: 827.428 | AE30: 827.428 | AF30: 0 | AG30: 0 | AI30: 0 | AJ30: -298.472 | AK30: -53.1 | AL30: 1179 | AP30: 0 | AQ30: 1052.68 | AR30: 12 | AS30: 0 | AT30: 0 | AU30: 0.5 | AV30: 0 | AW30: 0 | AX30: 0.1 | AY30: Tiny Kingdom | AZ30: Lehenga Choli | BC30: 0 | BD30: 0 | BE30: 0 | BF30: 0 | BG30: 0 | BJ30: 24.78 | BK30: 0 | BL30: 292.156 | BM30: -292.156 | BN30: 0 | BO30: 0 | BP30: 0 | BQ30: 3150 | BR30: 1.05268 | BS30: f904280d-7fc3-4611-9396-855af41a3fe7 | BT30: 0 | BU30: 5.263 | BV30: 0 | BW30: 1.053 | BX30: 827.428 | BY30: 0 | BZ30: 0 | CA30: 0 | CB30: 0 | CC30: 0 | CD30: 0 | CE30: 0 | CF30: 0 | CG30: 0 | CH30: 0 | CI30: 0 | CJ30: 0 | CK30: 0 | CL30: 0 | CM30: 0 | CN30: 0 | CO30: 0 | CP30: 0 | CQ30: 0 | CR30: 0 | CS30: 0 | CT30: 0 | CU30: 0 | CV30: 0 | CW30: 0 | CX30: 0 | CY30: 0 | CZ30: 0 | DA30: 0 | DB30: 0 | DC30: =IFERROR(G30,0)+IFERROR(H30,0) -> 1179 | DD30: =ABS(IFERROR(T30,0)) -> 292.156 | DE30: =ABS(IFERROR(P30,0)+IFERROR(Q30,0)) -> 6.316 | DF30: =ABS(IFERROR(AH30,0))+ABS(IFERROR(AK30,0))+IFERROR(W30,0) -> 53.1 | DG30: =IFERROR(M30,0)+IFERROR(N30,0)+IFERROR(O30,0)+IFERROR(P30,0) -> 131.583 | DH30: 827.428
A31: 8744260042 | B31: 10744268480 | C31: 45939.576 | D31: 45945.792 | E31: TNBYCLST116455372 | F31: 3102 | G31: 0 | H31: 3102 | I31: 3500 | J31: 192 | K31: Inter-State | L31: 18 | M31: 473.19 | N31: 0 | O31: 0 | P31: 13.144 | Q31: 2.629 | R31: 25.96 | S31: 805.279 | T31: -805.279 | U31: -821.052 | V31: -71.98 | W31: 0 | X31: 61 | Y31: 0 | Z31: 10.98 | AA31: 1 | AB31: NATIONAL | AC31: 3308 | AD31: 2208.968 | AE31: 2208.968 | AF31: 0 | AG31: -821.052 | AH31: -71.98 | AI31: 3102 | AJ31: 0 | AL31: 0 | AM31: 45959 | AN31: 45959 | AO31: 45959 | AP31: 0 | AQ31: 2628.81 | AR31: 18 | AS31: 0 | AT31: 0 | AU31: 0.5 | AV31: 0 | AW31: 0 | AX31: 0.1 | AY31: Tiny Baby | AZ31: Clothing Set | BA31: 25.96 | BB31: 0 | BC31: 805.279 | BD31: -805.279 | BE31: 0 | BF31: 0 | BG31: 0 | BH31: 192 | BI31: 2.62881 | BL31: 0 | BM31: 0 | BN31: 0 | BO31: 0 | BP31: 0 | BS31: 9db4bc3d-779d-419c-9e0b-9fca42469f0b | BT31: 13.144 | BU31: 0 | BV31: 2.629 | BW31: 0 | BX31: 0 | BY31: 0 | BZ31: 0 | CA31: 0 | CB31: 0 | CC31: 0 | CD31: 0 | CE31: 0 | CF31: 0 | CG31: 0 | CH31: 0 | CI31: 0 | CJ31: 0 | CK31: 0 | CL31: 2208.968 | CM31: 0 | CN31: 0 | CO31: 0 | CP31: 0 | CQ31: 0 | CR31: 0 | CS31: 0 | CT31: 0 | CU31: 0 | CV31: 0 | CW31: 0 | CX31: 0 | CY31: 0 | CZ31: 0 | DA31: 0 | DB31: 0 | DC31: =IFERROR(G31,0)+IFERROR(H31,0) -> 3102 | DD31: =ABS(IFERROR(T31,0)) -> 805.279 | DE31: =ABS(IFERROR(P31,0)+IFERROR(Q31,0)) -> 15.773 | DF31: =ABS(IFERROR(AH31,0))+ABS(IFERROR(AK31,0))+IFERROR(W31,0) -> 71.98 | DG31: =IFERROR(M31,0)+IFERROR(N31,0)+IFERROR(O31,0)+IFERROR(P31,0) -> 486.334 | DH31: 2208.968
A32: 8691422928 | B32: 10691351165 | C32: 45922.443 | D32: 45927.498 | E32: TIKILHNC113049608 | F32: 3564 | G32: 0 | H32: 3564 | I32: 4000 | J32: 230 | K32: Inter-State | L32: 18 | M32: 543.66 | N32: 0 | O32: 0 | P32: 15.102 | Q32: 3.02 | R32: 24.78 | S32: 883.159 | T32: -883.159 | U32: -901.281 | V32: -71.98 | W32: 0 | X32: 61 | Y32: 0 | Z32: 10.98 | AA32: 1 | AB32: ZONAL | AC32: 3770 | AD32: 2590.739 | AE32: 2590.739 | AF32: 0 | AG32: -901.281 | AH32: -71.98 | AI32: 3564 | AJ32: 0 | AL32: 0 | AM32: 45943 | AN32: 45943 | AO32: 45943 | AP32: 0 | AQ32: 3020.34 | AR32: 18 | AS32: 0 | AT32: 0 | AU32: 0.5 | AV32: 0 | AW32: 0 | AX32: 0.1 | AY32: Tiny Kingdom | AZ32: Lehenga Choli | BA32: 24.78 | BB32: 0 | BC32: 883.159 | BD32: -883.159 | BE32: 0 | BF32: 0 | BG32: 0 | BH32: 230 | BI32: 3.02034 | BL32: 0 | BM32: 0 | BN32: 0 | BO32: 0 | BP32: 0 | BS32: 15894860-f24f-4ec8-b4a5-016708217bcc | BT32: 15.102 | BU32: 0 | BV32: 3.02 | BW32: 0 | BX32: 0 | BY32: 0 | BZ32: 0 | CA32: 0 | CB32: 0 | CC32: 2590.739 | CD32: 0 | CE32: 0 | CF32: 0 | CG32: 0 | CH32: 0 | CI32: 0 | CJ32: 0 | CK32: 0 | CL32: 0 | CM32: 0 | CN32: 0 | CO32: 0 | CP32: 0 | CQ32: 0 | CR32: 0 | CS32: 0 | CT32: 0 | CU32: 0 | CV32: 0 | CW32: 0 | CX32: 0 | CY32: 0 | CZ32: 0 | DA32: 0 | DB32: 0 | DC32: =IFERROR(G32,0)+IFERROR(H32,0) -> 3564 | DD32: =ABS(IFERROR(T32,0)) -> 883.159 | DE32: =ABS(IFERROR(P32,0)+IFERROR(Q32,0)) -> 18.122 | DF32: =ABS(IFERROR(AH32,0))+ABS(IFERROR(AK32,0))+IFERROR(W32,0) -> 71.98 | DG32: =IFERROR(M32,0)+IFERROR(N32,0)+IFERROR(O32,0)+IFERROR(P32,0) -> 558.762 | DH32: 2590.739
A33: 8694664241 | B33: 10694592678 | C33: 45922.443 | D33: 45925.558 | E33: BETYDRSS67468522 | F33: 2293 | G33: 190.722 | H33: 2102.278 | I33: 4500 | J33: 2001 | K33: Intra-State | L33: 5 | M33: 0 | N33: 54.6 | O33: 54.6 | P33: 10.919 | Q33: 2.184 | R33: 31.86 | S33: 730.55 | T33: -730.55 | U33: -743.653 | V33: -71.98 | W33: 0 | X33: 61 | Y33: 0 | Z33: 10.98 | AA33: 1 | AB33: LOCAL | AC33: 2499 | AD33: 1477.367 | AE33: 1477.367 | AF33: 0 | AG33: -681.799 | AH33: -65.99268 | AI33: 2102.278 | AJ33: -61.854 | AK33: -5.98732 | AL33: 190.722 | AM33: 45939 | AN33: 45939 | AO33: 45939 | AP33: 175 | AQ33: 2183.8 | AR33: 0 | AS33: 2.5 | AT33: 2.5 | AU33: 0 | AV33: 0.25 | AW33: 0.25 | AX33: 0.1 | AY33: BETTY | AZ33: Dresses | BA33: 31.86 | BB33: 0 | BC33: 669.786 | BD33: -669.786 | BE33: 0 | BF33: 0 | BG33: 0 | BH33: 2001 | BI33: 2.1838 | BJ33: 31.86 | BK33: 0 | BL33: 60.764 | BM33: -60.764 | BN33: 0 | BO33: 0 | BP33: 0 | BQ33: 2001 | BR33: 2.1838 | BS33: 1ac17d49-ac26-47ec-9b63-d58b111dad1d | BT33: 10.011 | BU33: 0.908 | BV33: 2.002 | BW33: 0.182 | BX33: 0 | BY33: 0 | BZ33: 0 | CA33: 1477.367 | CB33: 0 | CC33: 0 | CD33: 0 | CE33: 0 | CF33: 0 | CG33: 0 | CH33: 0 | CI33: 0 | CJ33: 0 | CK33: 0 | CL33: 0 | CM33: 0 | CN33: 0 | CO33: 0 | CP33: 0 | CQ33: 0 | CR33: 0 | CS33: 0 | CT33: 0 | CU33: 0 | CV33: 0 | CW33: 0 | CX33: 0 | CY33: 0 | CZ33: 0 | DA33: 0 | DB33: 0 | DC33: =IFERROR(G33,0)+IFERROR(H33,0) -> 2293 | DD33: =ABS(IFERROR(T33,0)) -> 730.55 | DE33: =ABS(IFERROR(P33,0)+IFERROR(Q33,0)) -> 13.103 | DF33: =ABS(IFERROR(AH33,0))+ABS(IFERROR(AK33,0))+IFERROR(W33,0) -> 71.98 | DG33: =IFERROR(M33,0)+IFERROR(N33,0)+IFERROR(O33,0)+IFERROR(P33,0) -> 120.119 | DH33: 1477.367
A34: 8686235629 | B34: 10686163041 | C34: 45920.474 | D34: 45925.708 | E34: TIKILHNC115963237 | F34: 4219 | G34: 0 | H34: 4219 | I34: 4750 | J34: 325 | K34: Inter-State | L34: 12 | M34: 452.04 | N34: 0 | O34: 0 | P34: 18.835 | Q34: 3.767 | R34: 24.78 | S34: 1045.468 | T34: -1045.468 | U34: -1068.07 | V34: -71.98 | W34: 0 | X34: 61 | Y34: 0 | Z34: 10.98 | AA34: 1 | AB34: NATIONAL | AC34: 4425 | AD34: 3078.95 | AE34: 3078.95 | AF34: 0 | AG34: -1068.07 | AH34: -71.98 | AI34: 4219 | AJ34: 0 | AL34: 0 | AM34: 45939 | AN34: 45939 | AO34: 45939 | AP34: 0 | AQ34: 3766.96 | AR34: 12 | AS34: 0 | AT34: 0 | AU34: 0.5 | AV34: 0 | AW34: 0 | AX34: 0.1 | AY34: Tiny Kingdom | AZ34: Lehenga Choli | BA34: 24.78 | BB34: 0 | BC34: 1045.468 | BD34: -1045.468 | BE34: 0 | BF34: 0 | BG34: 0 | BH34: 325 | BI34: 3.76696 | BL34: 0 | BM34: 0 | BN34: 0 | BO34: 0 | BP34: 0 | BS34: bd29d170-44c4-4a5a-999e-3c5583be8674 | BT34: 18.835 | BU34: 0 | BV34: 3.767 | BW34: 0 | BX34: 0 | BY34: 0 | BZ34: 0 | CA34: 3078.95 | CB34: 0 | CC34: 0 | CD34: 0 | CE34: 0 | CF34: 0 | CG34: 0 | CH34: 0 | CI34: 0 | CJ34: 0 | CK34: 0 | CL34: 0 | CM34: 0 | CN34: 0 | CO34: 0 | CP34: 0 | CQ34: 0 | CR34: 0 | CS34: 0 | CT34: 0 | CU34: 0 | CV34: 0 | CW34: 0 | CX34: 0 | CY34: 0 | CZ34: 0 | DA34: 0 | DB34: 0 | DC34: =IFERROR(G34,0)+IFERROR(H34,0) -> 4219 | DD34: =ABS(IFERROR(T34,0)) -> 1045.468 | DE34: =ABS(IFERROR(P34,0)+IFERROR(Q34,0)) -> 22.602 | DF34: =ABS(IFERROR(AH34,0))+ABS(IFERROR(AK34,0))+IFERROR(W34,0) -> 71.98 | DG34: =IFERROR(M34,0)+IFERROR(N34,0)+IFERROR(O34,0)+IFERROR(P34,0) -> 470.875 | DH34: 3078.95
A35: 8743152600 | B35: 10743157156 | C35: 45939.449 | D35: 45943.626 | E35: TIKICLST113026329 | F35: 2410 | G35: 0 | H35: 2409.99 | I35: 3500 | J35: 884 | K35: Inter-State | L35: 5 | M35: 114.76 | N35: 0 | O35: 0 | P35: 11.476 | Q35: 2.295 | R35: 24.78 | S35: 597.196 | T35: -597.196 | U35: -610.967 | V35: -71.98 | W35: 0 | X35: 61 | Y35: 0 | Z35: 10.98 | AA35: 1 | AB35: ZONAL | AC35: 2616 | AD35: 1727.043 | AE35: 1727.043 | AF35: 0 | AG35: -610.967 | AH35: -71.98 | AI35: 2409.99 | AJ35: 0 | AL35: 0 | AM35: 45957 | AN35: 45957 | AO35: 45957 | AP35: 0 | AQ35: 2295.24 | AR35: 5 | AS35: 0 | AT35: 0 | AU35: 0.5 | AV35: 0 | AW35: 0 | AX35: 0.1 | AY35: Tiny Kingdom | AZ35: Clothing Set | BA35: 24.78 | BB35: 0 | BC35: 597.196 | BD35: -597.196 | BE35: 0 | BF35: 0 | BG35: 0 | BH35: 884 | BI35: 2.29524 | BL35: 0 | BM35: 0 | BN35: 0 | BO35: 0 | BP35: 0 | BS35: 9463124e-fb61-4e91-9e67-3b928c14486b | BT35: 11.476 | BU35: 0 | BV35: 2.295 | BW35: 0 | BX35: 0 | BY35: 0 | BZ35: 0 | CA35: 0 | CB35: 0 | CC35: 0 | CD35: 0 | CE35: 0 | CF35: 0 | CG35: 0 | CH35: 0 | CI35: 0 | CJ35: 1727.043 | CK35: 0 | CL35: 0 | CM35: 0 | CN35: 0 | CO35: 0 | CP35: 0 | CQ35: 0 | CR35: 0 | CS35: 0 | CT35: 0 | CU35: 0 | CV35: 0 | CW35: 0 | CX35: 0 | CY35: 0 | CZ35: 0 | DA35: 0 | DB35: 0 | DC35: =IFERROR(G35,0)+IFERROR(H35,0) -> 2409.99 | DD35: =ABS(IFERROR(T35,0)) -> 597.196 | DE35: =ABS(IFERROR(P35,0)+IFERROR(Q35,0)) -> 13.771 | DF35: =ABS(IFERROR(AH35,0))+ABS(IFERROR(AK35,0))+IFERROR(W35,0) -> 71.98 | DG35: =IFERROR(M35,0)+IFERROR(N35,0)+IFERROR(O35,0)+IFERROR(P35,0) -> 126.236 | DH35: 1727.043
A36: 8745416575 | B36: 10745429075 | C36: 45940.445 | D36: 45944.478 | E36: BETYDRSS51730850 | F36: 416 | G36: 0 | H36: 416 | I36: 2600 | J36: 2125 | K36: Inter-State | L36: 5 | M36: 19.81 | N36: 0 | O36: 0 | P36: 1.981 | Q36: 0.396 | R36: 8.26 | S36: 34.362 | T36: -34.362 | U36: -36.739 | V36: -31.86 | W36: 0 | X36: 27 | Y36: 0 | Z36: 4.86 | AA36: 1 | AB36: ZONAL | AC36: 475 | AD36: 347.401 | AE36: 347.401 | AF36: 0 | AG36: -36.739 | AH36: -31.86 | AI36: 416 | AJ36: 0 | AL36: 0 | AM36: 45958 | AN36: 45958 | AO36: 45958 | AP36: 0 | AQ36: 396.19 | AR36: 5 | AS36: 0 | AT36: 0 | AU36: 0.5 | AV36: 0 | AW36: 0 | AX36: 0.1 | AY36: BETTY | AZ36: Ethnic Dresses | BA36: 8.26 | BB36: 0 | BC36: 34.362 | BD36: -34.362 | BE36: 0 | BF36: 0 | BG36: 0 | BH36: 2125 | BI36: 0.39619 | BL36: 0 | BM36: 0 | BN36: 0 | BO36: 0 | BP36: 0 | BS36: af4528c0-1ab2-4623-a251-5a3b5fdb202a | BT36: 1.981 | BU36: 0 | BV36: 0.396 | BW36: 0 | BX36: 0 | BY36: 0 | BZ36: 0 | CA36: 0 | CB36: 0 | CC36: 0 | CD36: 0 | CE36: 0 | CF36: 0 | CG36: 0 | CH36: 0 | CI36: 0 | CJ36: 0 | CK36: 347.401 | CL36: 0 | CM36: 0 | CN36: 0 | CO36: 0 | CP36: 0 | CQ36: 0 | CR36: 0 | CS36: 0 | CT36: 0 | CU36: 0 | CV36: 0 | CW36: 0 | CX36: 0 | CY36: 0 | CZ36: 0 | DA36: 0 | DB36: 0 | DC36: =IFERROR(G36,0)+IFERROR(H36,0) -> 416 | DD36: =ABS(IFERROR(T36,0)) -> 34.362 | DE36: =ABS(IFERROR(P36,0)+IFERROR(Q36,0)) -> 2.377 | DF36: =ABS(IFERROR(AH36,0))+ABS(IFERROR(AK36,0))+IFERROR(W36,0) -> 31.86 | DG36: =IFERROR(M36,0)+IFERROR(N36,0)+IFERROR(O36,0)+IFERROR(P36,0) -> 21.791 | DH36: 347.401
A37: 8717347916 | B37: 10717288970 | C37: 45930.615 | D37: 45936.674 | E37: TIKIDRSS106641770 | F37: 3119 | G37: 0 | H37: 3119 | I37: 3750 | J37: 425 | K37: Inter-State | L37: 18 | M37: 475.78 | N37: 0 | O37: 0 | P37: 13.216 | Q37: 2.643 | R37: 21.24 | S37: 662.476 | T37: -662.476 | U37: -678.335 | V37: -71.98 | W37: 0 | X37: 61 | Y37: 0 | Z37: 10.98 | AA37: 1 | AB37: NATIONAL | AC37: 3325 | AD37: 2368.685 | AE37: 2368.685 | AF37: 0 | AG37: -678.335 | AH37: -71.98 | AI37: 3119 | AJ37: 0 | AL37: 0 | AM37: 45953 | AN37: 45953 | AO37: 45953 | AP37: 0 | AQ37: 2643.22 | AR37: 18 | AS37: 0 | AT37: 0 | AU37: 0.5 | AV37: 0 | AW37: 0 | AX37: 0.1 | AY37: Tiny Kingdom | AZ37: Dresses | BA37: 21.24 | BB37: 0 | BC37: 662.476 | BD37: -662.476 | BE37: 0 | BF37: 0 | BG37: 0 | BH37: 425 | BI37: 2.64322 | BL37: 0 | BM37: 0 | BN37: 0 | BO37: 0 | BP37: 0 | BS37: 6749a4da-1024-4e5b-b0d1-a406db8a17a8 | BT37: 13.216 | BU37: 0 | BV37: 2.643 | BW37: 0 | BX37: 0 | BY37: 0 | BZ37: 0 | CA37: 0 | CB37: 0 | CC37: 0 | CD37: 0 | CE37: 0 | CF37: 0 | CG37: 0 | CH37: 2368.685 | CI37: 0 | CJ37: 0 | CK37: 0 | CL37: 0 | CM37: 0 | CN37: 0 | CO37: 0 | CP37: 0 | CQ37: 0 | CR37: 0 | CS37: 0 | CT37: 0 | CU37: 0 | CV37: 0 | CW37: 0 | CX37: 0 | CY37: 0 | CZ37: 0 | DA37: 0 | DB37: 0 | DC37: =IFERROR(G37,0)+IFERROR(H37,0) -> 3119 | DD37: =ABS(IFERROR(T37,0)) -> 662.476 | DE37: =ABS(IFERROR(P37,0)+IFERROR(Q37,0)) -> 15.859 | DF37: =ABS(IFERROR(AH37,0))+ABS(IFERROR(AK37,0))+IFERROR(W37,0) -> 71.98 | DG37: =IFERROR(M37,0)+IFERROR(N37,0)+IFERROR(O37,0)+IFERROR(P37,0) -> 488.996 | DH37: 2368.685
A38: 8681243759 | B38: 10681169730 | C38: 45919.434 | D38: 45923.548 | E38: TIKICLST98837547 | F38: 2275 | G38: 0 | H38: 2275 | I38: 4750 | J38: 2138 | K38: Inter-State | L38: 12 | M38: 243.75 | N38: 0 | O38: 0 | P38: 10.156 | Q38: 2.031 | R38: 24.78 | S38: 563.745 | T38: -563.745 | U38: -575.932 | V38: -71.98 | W38: 0 | X38: 61 | Y38: 0 | Z38: 10.98 | AA38: 1 | AB38: NATIONAL | AC38: 2481 | AD38: 1627.088 | AE38: 1627.088 | AF38: 0 | AG38: -575.932 | AH38: -71.98 | AI38: 2275 | AJ38: 0 | AL38: 0 | AM38: 45938 | AN38: 45938 | AO38: 45938 | AP38: 0 | AQ38: 2031.25 | AR38: 12 | AS38: 0 | AT38: 0 | AU38: 0.5 | AV38: 0 | AW38: 0 | AX38: 0.1 | AY38: Tiny Kingdom | AZ38: Clothing Set | BA38: 24.78 | BB38: 0 | BC38: 563.745 | BD38: -563.745 | BE38: 0 | BF38: 0 | BG38: 0 | BH38: 2138 | BI38: 2.03125 | BL38: 0 | BM38: 0 | BN38: 0 | BO38: 0 | BP38: 0 | BS38: 0c5bf0f2-507f-470d-858a-0222f525feb5 | BT38: 10.156 | BU38: 0 | BV38: 2.031 | BW38: 0 | BX38: 0 | BY38: 0 | BZ38: 1627.088 | CA38: 0 | CB38: 0 | CC38: 0 | CD38: 0 | CE38: 0 | CF38: 0 | CG38: 0 | CH38: 0 | CI38: 0 | CJ38: 0 | CK38: 0 | CL38: 0 | CM38: 0 | CN38: 0 | CO38: 0 | CP38: 0 | CQ38: 0 | CR38: 0 | CS38: 0 | CT38: 0 | CU38: 0 | CV38: 0 | CW38: 0 | CX38: 0 | CY38: 0 | CZ38: 0 | DA38: 0 | DB38: 0 | DC38: =IFERROR(G38,0)+IFERROR(H38,0) -> 2275 | DD38: =ABS(IFERROR(T38,0)) -> 563.745 | DE38: =ABS(IFERROR(P38,0)+IFERROR(Q38,0)) -> 12.187 | DF38: =ABS(IFERROR(AH38,0))+ABS(IFERROR(AK38,0))+IFERROR(W38,0) -> 71.98 | DG38: =IFERROR(M38,0)+IFERROR(N38,0)+IFERROR(O38,0)+IFERROR(P38,0) -> 253.906 | DH38: 1627.088
A39: 8707877371 | B39: 10707811233 | C39: 45925.776 | D39: 45933.485 | E39: TIKICLST113026329 | F39: 3104 | G39: 3104 | H39: 0 | I39: 3500 | J39: 190 | K39: Inter-State | L39: 18 | M39: 473.49 | N39: 0 | O39: 0 | P39: 13.153 | Q39: 2.63 | R39: 24.78 | S39: 769.171 | T39: -769.171 | U39: -784.955 | V39: -71.98 | W39: 0 | X39: 61 | Y39: 0 | Z39: 10.98 | AA39: 1 | AB39: NATIONAL | AC39: 3310 | AD39: 2247.065 | AE39: 2247.065 | AF39: 0 | AG39: -704.054 | AH39: -64.56134 | AI39: 2784.09 | AJ39: -80.901 | AK39: -7.41866 | AL39: 319.91 | AM39: 45947 | AN39: 45947 | AO39: 45947 | AP39: 300 | AQ39: 2630.51 | AR39: 18 | AS39: 0 | AT39: 0 | AU39: 0.5 | AV39: 0 | AW39: 0 | AX39: 0.1 | AY39: Tiny Kingdom | AZ39: Clothing Set | BC39: 0 | BD39: 0 | BE39: 0 | BF39: 0 | BG39: 0 | BJ39: 24.78 | BK39: 0 | BL39: 769.171 | BM39: -769.171 | BN39: 0 | BO39: 0 | BP39: 0 | BQ39: 190 | BR39: 2.63051 | BS39: 700c0553-2296-4d34-8f2a-e0cf0593659c | BT39: 11.797 | BU39: 1.356 | BV39: 2.359 | BW39: 0.271 | BX39: 0 | BY39: 0 | BZ39: 0 | CA39: 0 | CB39: 0 | CC39: 0 | CD39: 0 | CE39: 0 | CF39: 0 | CG39: 2247.065 | CH39: 0 | CI39: 0 | CJ39: 0 | CK39: 0 | CL39: 0 | CM39: 0 | CN39: 0 | CO39: 0 | CP39: 0 | CQ39: 0 | CR39: 0 | CS39: 0 | CT39: 0 | CU39: 0 | CV39: 0 | CW39: 0 | CX39: 0 | CY39: 0 | CZ39: 0 | DA39: 0 | DB39: 0 | DC39: =IFERROR(G39,0)+IFERROR(H39,0) -> 3104 | DD39: =ABS(IFERROR(T39,0)) -> 769.171 | DE39: =ABS(IFERROR(P39,0)+IFERROR(Q39,0)) -> 15.783 | DF39: =ABS(IFERROR(AH39,0))+ABS(IFERROR(AK39,0))+IFERROR(W39,0) -> 71.98 | DG39: =IFERROR(M39,0)+IFERROR(N39,0)+IFERROR(O39,0)+IFERROR(P39,0) -> 486.643 | DH39: 2247.066
